Workbook
Name AKTIVALAINNYA: CONTROL!$G$9
Name AKTIVALANCARLAINNYA: CONTROL!$G$6
Name AKTIVATETAP: CONTROL!$G$7
Name AKUNPIUTANG: CONTROL!$G$4
Name AKUNUTANG: CONTROL!$G$10
Name BEBAN: CONTROL!$G$21
Name BEBANLAINNYA: CONTROL!$G$22
Name COA_DEBET: COA!$E$5:$E$59
Name COA_KREDIT: COA!$F$5:$F$59
Name DEPRESIASIDANAMORTISASI: CONTROL!$G$8
Name EKUITAS: CONTROL!$G$17
Name JU_BB: JURNAL!$J$7:$J$226
Name JU_Debet: JURNAL!$G$7:$G$228
Name JU_Keterangan: JURNAL!$D$7:$D$228
Name JU_Kodeakun: JURNAL!$E$7:$E$228
Name JU_Kredit: JURNAL!$H$7:$H$228
Name JU_Namaakun: JURNAL!$F$7:$F$228
Name JU_REF: JURNAL!$C$7:$C$242
Name JU_Tanggal: JURNAL!$B$7:$B$244
Name KASDANBANK: CONTROL!$G$3
Name KEWAJIBANJANGKAPANJANG: CONTROL!$G$12
Name KEWAJIBANLANCARLAINNYA: CONTROL!$G$11
Name KODEAKUN: COA!$B$5:$B$86
Name LRSLDO: LR!$K$6:$K$45
Name LRTYPE: LR!$J$6:$J$94
Name Nama_Akun: CONTROL!$B$3:$B$84
Name NRC_TYPE: NRC!$I$8:$I$24
Name NRCL: NRL!$F:$F
Name NRCLDB: NRL!$M:$M
Name NRCLDB2: NRL!$O:$O
Name NRCLKODE: NRL!$B:$B
Name NRCLKR: NRL!$N:$N
Name NRCLKR2: NRL!$P:$P
Name NRCLSN: NRL!$F:$F
Name NRCSALDO: NRC!$J$8:$J$24
Name PEMBELIAN: CONTROL!$G$20
Name PENDAPATAN: CONTROL!$G$18
Name PENDAPATANLAINNYA: CONTROL!$G$19
Name PERSEDIAAN: CONTROL!$G$5
Name Posisi: CONTROL!$D$3:$D$84
Name SaldoNormal: CONTROL!$C$3:$C$84
Name Type: CONTROL!$B$3:$B$84

Sheet MENU
C17: Pencatatan dan Pelaporan Akuntansi Keuangan

Sheet COA
B2: DAFTAR AKUN
B4: Kode Akun | C4: Nama Akun | D4: Type | E4: Debet | F4: Kredit | H4: SN | I4: POS
B5: 1101 | C5: Kas | D5: Kas | H5: =VLOOKUP(D5,CONTROL!$B$3:$D$84,2,TRUE) -> Debet | I5: =VLOOKUP(D5,CONTROL!B3:D84,3,FALSE) -> Neraca
B6: 1102 | C6: Kas Di Bank | D6: Kas Di Bank | H6: =VLOOKUP(D6,CONTROL!$B$3:$D$84,2,TRUE) -> Debet | I6: =VLOOKUP(D6,CONTROL!B4:D85,3,FALSE) -> Neraca
B7: 1103 | C7: Petty Cash | D7: Petty Cash | H7: =VLOOKUP(D7,CONTROL!$B$3:$D$84,2,TRUE) -> Debet | I7: =VLOOKUP(D7,CONTROL!B5:D86,3,FALSE) -> Neraca
B8: 1104 | C8: Piutang | D8: Piutang | H8: =VLOOKUP(D8,CONTROL!$B$3:$D$84,2,TRUE) -> Debet | I8: =VLOOKUP(D8,CONTROL!B6:D87,3,FALSE) -> Neraca
B9: 1105 | C9: Persediaan | D9: Persediaan | H9: =VLOOKUP(D9,CONTROL!$B$3:$D$84,2,TRUE) -> Debet | I9: =VLOOKUP(D9,CONTROL!B7:D87,3,FALSE) -> Neraca
B10: 1106 | C10: Perlengkapan | D10: Perlengkapan | H10: =VLOOKUP(D10,CONTROL!$B$3:$D$84,2,TRUE) -> Debet | I10: =VLOOKUP(D10,CONTROL!B8:D88,3,FALSE) -> Neraca
B11: 1201 | C11: Peralatan | D11: Peralatan | H11: =VLOOKUP(D11,CONTROL!$B$3:$D$84,2,TRUE) -> Debet | I11: =VLOOKUP(D11,CONTROL!B9:D89,3,FALSE) -> Neraca
B12: 1202 | C12: Akumulasi Penyusutan Peralatan | D12: Akumulasi Penyusutan Peralatan | H12: =VLOOKUP(COA!D12,CONTROL!B3:D84,2,FALSE) -> Kredit | I12: =VLOOKUP(D12,CONTROL!B10:D90,3,FALSE) -> Neraca
B13: 2110 | C13: Utang | D13: Utang | H13: =VLOOKUP(COA!D13,CONTROL!B4:D85,2,FALSE) -> Kredit | I13: =VLOOKUP(D13,CONTROL!B11:D91,3,FALSE) -> Neraca
B14: 2120 | C14: Utang Gaji | D14: Utang Gaji | H14: =VLOOKUP(COA!D14,CONTROL!B5:D86,2,FALSE) -> Kredit | I14: =VLOOKUP(D14,CONTROL!B12:D92,3,FALSE) -> Neraca
B15: 2130 | C15: utang pajak | D15: utang pajak | H15: =VLOOKUP(COA!D15,CONTROL!B6:D87,2,FALSE) -> Kredit | I15: =VLOOKUP(D15,CONTROL!B13:D93,3,FALSE) -> Neraca
B16: 2140 | C16: utang pdam | D16: utang pdam | H16: =VLOOKUP(COA!D16,CONTROL!B7:D88,2,FALSE) -> Kredit | I16: =VLOOKUP(D16,CONTROL!B14:D94,3,FALSE) -> Neraca
B17: 2150 | C17: utang jne | D17: utang jne | H17: =VLOOKUP(COA!D17,CONTROL!B8:D89,2,FALSE) -> Kredit | I17: =VLOOKUP(D17,CONTROL!B15:D95,3,FALSE) -> Neraca
B18: 2160 | C18: utang pcp | D18: utang pcp | H18: =VLOOKUP(COA!D18,CONTROL!B9:D90,2,FALSE) -> Kredit | I18: =VLOOKUP(D18,CONTROL!B16:D96,3,FALSE) -> Neraca
B19: 3100 | C19: Modal | D19: Modal | H19: =VLOOKUP(COA!D19,CONTROL!B10:D91,2,FALSE) -> Kredit | I19: =VLOOKUP(D19,CONTROL!B17:D97,3,FALSE) -> Neraca
B20: 3110 | C20: Iktisar laba rugi | D20: Iktisar laba rugi | H20: =VLOOKUP(COA!D20,CONTROL!B11:D92,2,FALSE) -> Kredit | I20: =VLOOKUP(D20,CONTROL!B18:D98,3,FALSE) -> Neraca
B21: 4110 | C21: Pendapatan jasa | D21: Pendapatan jasa | H21: =VLOOKUP(COA!D21,CONTROL!B12:D93,2,FALSE) -> Kredit | I21: =VLOOKUP(D21,CONTROL!B19:D99,3,FALSE) -> Laba Rugi
B22: 4120 | C22: pendapatan shoepolice | D22: pendapatan shoepolice | H22: =VLOOKUP(COA!D22,CONTROL!B13:D94,2,FALSE) -> Kredit | I22: =VLOOKUP(D22,CONTROL!B20:D100,3,FALSE) -> Laba Rugi
B23: 4130 | C23: pendapatan affiliate | D23: pendapatan affiliate | H23: =VLOOKUP(COA!D23,CONTROL!B14:D95,2,FALSE) -> Kredit | I23: =VLOOKUP(D23,CONTROL!B21:D101,3,FALSE) -> Laba Rugi
... B85: 8010 | C85: Pajak | D85: Pajak | H85: =VLOOKUP(COA!D85,CONTROL!B76:D157,2,FALSE) -> Debet | I85: =VLOOKUP(D85,CONTROL!B83:D163,3,FALSE) -> Laba Rugi

Sheet CONTROL
F1: Arus kas
B2: TYPE Akun | C2: Saldo Normal | D2: Posisi | F2: Type
B3: Kas | C3: Debet | D3: Neraca | F3: KAS DAN BANK | G3: =SUMIF(NRC_TYPE,F3,NRCSALDO) -> 0
B4: Kas Di Bank | C4: Debet | D4: Neraca | F4: AKUN PIUTANG | G4: =SUMIF(NRC_TYPE,F4,NRCSALDO) -> 0
B5: Petty Cash | C5: Debet | D5: Neraca | F5: PERSEDIAAN | G5: =SUMIF(NRC_TYPE,F5,NRCSALDO) -> 0
B6: Piutang | C6: Debet | D6: Neraca | F6: AKTIVA LANCAR LAINNYA | G6: =SUMIF(NRC_TYPE,F6,NRCSALDO) -> 0
B7: Persediaan | C7: Debet | D7: Neraca | F7: AKTIVA TETAP | G7: =SUMIF(NRC_TYPE,F7,NRCSALDO) -> -515685
B8: Perlengkapan | C8: Debet | D8: Neraca | F8: DEPRESIASI DAN AMORTISASI | G8: =-SUMIF(NRC_TYPE,F8,NRCSALDO) -> 0
B9: Peralatan | C9: Debet | D9: Neraca | F9: AKTIVA LAINNYA | G9: =SUMIF(NRC_TYPE,F9,NRCSALDO) -> 0
B10: Akumulasi Penyusutan Peralatan | C10: Kredit | D10: Neraca | F10: AKUN UTANG | G10: =SUMIF(NRC_TYPE,F10,NRCSALDO) -> 0
B11: Utang | C11: Kredit | D11: Neraca | F11: KEWAJIBAN LANCAR LAINNYA | G11: =SUMIF(NRC_TYPE,F11,NRCSALDO) -> 0
B12: Utang Gaji | C12: Kredit | D12: Neraca | F12: KEWAJIBAN JANGKA PANJANG | G12: =SUMIF(NRC_TYPE,F12,NRCSALDO) -> 0
B13: utang pajak | C13: Kredit | D13: Neraca
B14: utang pdam | C14: Kredit | D14: Neraca
B15: utang jne | C15: Kredit | D15: Neraca
B16: utang pcp | C16: Kredit | D16: Neraca
B17: Modal | C17: Kredit | D17: Neraca | F17: EKUITAS | G17: =SUMIF(NRC_TYPE,F17,NRCSALDO) -> #N/A
B18: Iktisar laba rugi | C18: Kredit | D18: Neraca | F18: PENDAPATAN | G18: =SUMIF(LRTYPE,F18,LRSLDO) -> #REF!
B19: Pendapatan jasa | C19: Kredit | D19: Laba Rugi | F19: PENDAPATAN LAINNYA | G19: =SUMIF(LRTYPE,F19,LRSLDO) -> 0
B20: pendapatan shoepolice | C20: Kredit | D20: Laba Rugi | F20: Pembelian | G20: =-SUMIF(LRTYPE,F20,LRSLDO) -> #REF!
B21: pendapatan affiliate | C21: Kredit | D21: Laba Rugi | F21: BEBAN | G21: =-SUMIF(LRTYPE,F21,LRSLDO) -> #REF!
B22: pendapatan jasa eiger | C22: Kredit | D22: Laba Rugi | F22: BEBAN LAINNYA | G22: =-SUMIF(LRTYPE,F22,LRSLDO) -> #REF!
B23: pendapatan lain-lain | C23: Kredit | D23: Laba Rugi
B24: pendapatan ongkir | C24: Kredit | D24: Laba Rugi
B25: Retur & Refund | C25: Debet | D25: Laba Rugi
B26: Hpp sole | C26: Debet | D26: Laba Rugi
B27: Hpp upper | C27: Debet | D27: Laba Rugi
B28: Hpp reguler | C28: Debet | D28: Laba Rugi
B29: Hpp Vibram | C29: Debet | D29: Laba Rugi
B30: Hpp repaint | C30: Debet | D30: Laba Rugi
B31: Hpp general | C31: Debet | D31: Laba Rugi
B32: Hpp Aksesoris | C32: Debet | D32: Laba Rugi
B33: Beban Gaji shoepolice | C33: Debet | D33: Laba Rugi
B34: Beban Gaji Workshop | C34: Debet | D34: Laba Rugi
... B83: Pajak | C83: Debet | D83: Laba Rugi

Sheet JURNAL
B2: FORM Jurnal
F4: =IF(G4=H4,"BALANCE","CEK KEMBALI") -> CEK KEMBALI | G4: =SUM(G7:G180) -> 129849716 | H4: =SUM(H7:H180) -> 207577079
B6: Tanggal | C6: Ref | D6: Keterangan | E6: Kode Akun | F6: Nama Akun | G6: Debet | H6: Kredit | J6: KB BB
B7: 01 juni 2026 | D7: Pendapatan jasa | E7: 4110 | F7: {=IFERROR(INDEX(COA!$C$5:$C$59,MATCH(JURNAL!E7,COA!$B$5:$B$59,0)),"")} -> Pendapatan jasa | G7: 6912662 | J7: =IF(E7="","",COUNTIF($E$7:E7,E7)&E7) -> 14110
B8: 01 juni 2026 | D8: Pengembalian kelebihan perjalanan dinas | F8: {=IFERROR(INDEX(COA!$C$5:$C$59,MATCH(JURNAL!E8,COA!$B$5:$B$59,0)),"")} | G8: 392280 | J8: =IF(E8="","",COUNTIF($E$7:E8,E8)&E8)
B9: 01 juni 2026 | D9: kopi, gula, teh ws | E9: 6080 | F9: {=IFERROR(INDEX(COA!$C$5:$C$59,MATCH(JURNAL!E9,COA!$B$5:$B$59,0)),"")} | H9: 76500 | J9: =IF(E9="","",COUNTIF($E$7:E9,E9)&E9) -> 16080
B10: 01 juni 2026 | D10: MITRA | E10: 5010 | F10: {=IFERROR(INDEX(COA!$C$5:$C$59,MATCH(JURNAL!E10,COA!$B$5:$B$59,0)),"")} -> Hpp sole | H10: 133500 | J10: =IF(E10="","",COUNTIF($E$7:E10,E10)&E10) -> 15010
B11: 01 juni 2026 | D11: MEGA | E11: 5010 | F11: {=IFERROR(INDEX(COA!$C$5:$C$59,MATCH(JURNAL!E11,COA!$B$5:$B$59,0)),"")} -> Hpp sole | H11: 316500 | J11: =IF(E11="","",COUNTIF($E$7:E11,E11)&E11) -> 25010
B12: 01 juni 2026 | D12: SUMBER | E12: 5010 | F12: {=IFERROR(INDEX(COA!$C$5:$C$59,MATCH(JURNAL!E12,COA!$B$5:$B$59,0)),"")} -> Hpp sole | H12: 424000 | J12: =IF(E12="","",COUNTIF($E$7:E12,E12)&E12) -> 35010
B13: 01 juni 2026 | D13: OUTLET KITA | E13: 5010 | F13: {=IFERROR(INDEX(COA!$C$5:$C$59,MATCH(JURNAL!E13,COA!$B$5:$B$59,0)),"")} -> Hpp sole | H13: 649799 | J13: =IF(E13="","",COUNTIF($E$7:E13,E13)&E13) -> 45010
B14: 01 juni 2026 | D14: SOLE BOLA | E14: 5010 | F14: {=IFERROR(INDEX(COA!$C$5:$C$59,MATCH(JURNAL!E14,COA!$B$5:$B$59,0)),"")} -> Hpp sole | H14: 18970 | J14: =IF(E14="","",COUNTIF($E$7:E14,E14)&E14) -> 55010
B15: 01 juni 2026 | D15: BANTAL TUMIT | E15: 5010 | F15: {=IFERROR(INDEX(COA!$C$5:$C$59,MATCH(JURNAL!E15,COA!$B$5:$B$59,0)),"")} -> Hpp sole | H15: 5968 | J15: =IF(E15="","",COUNTIF($E$7:E15,E15)&E15) -> 65010
B16: 01 juni 2026 | D16: SOLE BADMINTON | E16: 5010 | F16: {=IFERROR(INDEX(COA!$C$5:$C$59,MATCH(JURNAL!E16,COA!$B$5:$B$59,0)),"")} -> Hpp sole | H16: 43620 | J16: =IF(E16="","",COUNTIF($E$7:E16,E16)&E16) -> 75010
B17: 01 juni 2026 | D17: HEEL PATCH CONVERS | E17: 5010 | F17: {=IFERROR(INDEX(COA!$C$5:$C$59,MATCH(JURNAL!E17,COA!$B$5:$B$59,0)),"")} -> Hpp sole | H17: 17648 | J17: =IF(E17="","",COUNTIF($E$7:E17,E17)&E17) -> 85010
B18: 01 juni 2026 | D18: BIAYA KIRIMAN KULIT | E18: 5310 | F18: {=IFERROR(INDEX(COA!$C$5:$C$59,MATCH(JURNAL!E18,COA!$B$5:$B$59,0)),"")} -> Biaya ekspedisi & ongkir | H18: 58975 | J18: =IF(E18="","",COUNTIF($E$7:E18,E18)&E18) -> 15310
B19: 01 juni 2026 | D19: vibram | E19: 5040 | F19: {=IFERROR(INDEX(COA!$C$5:$C$59,MATCH(JURNAL!E19,COA!$B$5:$B$59,0)),"")} -> Hpp Vibram | H19: 497000 | J19: =IF(E19="","",COUNTIF($E$7:E19,E19)&E19) -> 15040
B20: 01 juni 2026 | D20: BENSIN KIMKO | E20: 6000 | F20: {=IFERROR(INDEX(COA!$C$5:$C$59,MATCH(JURNAL!E20,COA!$B$5:$B$59,0)),"")} | H20: 20000 | J20: =IF(E20="","",COUNTIF($E$7:E20,E20)&E20) -> 16000
... B25: 01 juni 2026 | D25: gaji bulanan mei | E25: 2120 | F25: {=IFERROR(INDEX(COA!$C$5:$C$59,MATCH(JURNAL!E25,COA!$B$5:$B$59,0)),"")} -> Utang Gaji | H25: 94000000 | J25: =IF(E25="","",COUNTIF($E$7:E25,E25)&E25) -> 12120
B26: 01 juni 2026 | D26: prive | F26: {=IFERROR(INDEX(COA!$C$5:$C$59,MATCH(JURNAL!E26,COA!$B$5:$B$59,0)),"")} | H26: 100000 | J26: =IF(E26="","",COUNTIF($E$7:E26,E26)&E26)
B27: 01 juni 2026 | D27: selisih ayat silang | F27: {=IFERROR(INDEX(COA!$C$5:$C$59,MATCH(JURNAL!E27,COA!$B$5:$B$59,0)),"")} | H27: 325 | J27: =IF(E27="","",COUNTIF($E$7:E27,E27)&E27)
B28: 2 juni 2026 | D28: pendapatan jasa | E28: 4110 | F28: {=IFERROR(INDEX(COA!$C$5:$C$59,MATCH(JURNAL!E28,COA!$B$5:$B$59,0)),"")} -> Pendapatan jasa | G28: 8122933 | J28: =IF(E28="","",COUNTIF($E$7:E28,E28)&E28) -> 24110
B29: 2 juni 2026 | D29: iuran office/sortir | E29: 6020 | F29: {=IFERROR(INDEX(COA!$C$5:$C$59,MATCH(JURNAL!E29,COA!$B$5:$B$59,0)),"")} | H29: 250000 | J29: =IF(E29="","",COUNTIF($E$7:E29,E29)&E29) -> 16020
B30: 2 juni 2026 | D30: ongkir cust pick up tunggu pengembalian | E30: 5310 | F30: {=IFERROR(INDEX(COA!$C$5:$C$59,MATCH(JURNAL!E30,COA!$B$5:$B$59,0)),"")} -> Biaya ekspedisi & ongkir | H30: 80360 | J30: =IF(E30="","",COUNTIF($E$7:E30,E30)&E30) -> 25310
B31: 2 juni 2026 | D31: meeting | E31: 5200 | F31: {=IFERROR(INDEX(COA!$C$5:$C$59,MATCH(JURNAL!E31,COA!$B$5:$B$59,0)),"")} -> Konsumsi lembur & Meeting | H31: 95000 | J31: =IF(E31="","",COUNTIF($E$7:E31,E31)&E31) -> 15200
B32: 2 juni 2026 | D32: ongkir an fauzi | E32: 5310 | F32: {=IFERROR(INDEX(COA!$C$5:$C$59,MATCH(JURNAL!E32,COA!$B$5:$B$59,0)),"")} -> Biaya ekspedisi & ongkir | H32: 73000 | J32: =IF(E32="","",COUNTIF($E$7:E32,E32)&E32) -> 35310
B33: 2 juni 2026 | D33: atk | E33: 6030 | F33: {=IFERROR(INDEX(COA!$C$5:$C$59,MATCH(JURNAL!E33,COA!$B$5:$B$59,0)),"")} | H33: 187000 | J33: =IF(E33="","",COUNTIF($E$7:E33,E33)&E33) -> 16030
B34: 2 juni 2026 | D34: pajak sisa bayar th 2022 & 2024 | E34: 8010 | F34: {=IFERROR(INDEX(COA!$C$5:$C$59,MATCH(JURNAL!E34,COA!$B$5:$B$59,0)),"")} | H34: 507960 | J34: =IF(E34="","",COUNTIF($E$7:E34,E34)&E34) -> 18010
B35: 2 juni 2026 | D35: MITRA | E35: 5010 | F35: {=IFERROR(INDEX(COA!$C$5:$C$59,MATCH(JURNAL!E35,COA!$B$5:$B$59,0)),"")} -> Hpp sole | H35: 20500 | J35: =IF(E35="","",COUNTIF($E$7:E35,E35)&E35) -> 105010
B36: 2 juni 2026 | D36: SUMBER | E36: 5010 | F36: {=IFERROR(INDEX(COA!$C$5:$C$59,MATCH(JURNAL!E36,COA!$B$5:$B$59,0)),"")} -> Hpp sole | H36: 56000 | J36: =IF(E36="","",COUNTIF($E$7:E36,E36)&E36) -> 115010
B37: 2 juni 2026 | D37: MEGA | E37: 5010 | F37: {=IFERROR(INDEX(COA!$C$5:$C$59,MATCH(JURNAL!E37,COA!$B$5:$B$59,0)),"")} -> Hpp sole | H37: 81000 | J37: =IF(E37="","",COUNTIF($E$7:E37,E37)&E37) -> 125010
B38: 2 juni 2026 | D38: AFUNG | E38: 5030 | F38: {=IFERROR(INDEX(COA!$C$5:$C$59,MATCH(JURNAL!E38,COA!$B$5:$B$59,0)),"")} -> Hpp reguler | H38: 930000 | J38: =IF(E38="","",COUNTIF($E$7:E38,E38)&E38) -> 15030
B39: 2 juni 2026 | D39: BEN | E39: 5030 | F39: {=IFERROR(INDEX(COA!$C$5:$C$59,MATCH(JURNAL!E39,COA!$B$5:$B$59,0)),"")} -> Hpp reguler | H39: 524000 | J39: =IF(E39="","",COUNTIF($E$7:E39,E39)&E39) -> 25030
B40: 2 juni 2026 | D40: JUMBO | E40: 5030 | F40: {=IFERROR(INDEX(COA!$C$5:$C$59,MATCH(JURNAL!E40,COA!$B$5:$B$59,0)),"")} -> Hpp reguler | H40: 61000 | J40: =IF(E40="","",COUNTIF($E$7:E40,E40)&E40) -> 35030
... B45: 2 juni 2026 | D45: sewa sorrtir | E45: 5630 | F45: {=IFERROR(INDEX(COA!$C$5:$C$59,MATCH(JURNAL!E45,COA!$B$5:$B$59,0)),"")} | H45: 2750000 | J45: =IF(E45="","",COUNTIF($E$7:E45,E45)&E45) -> 15630
B46: 3 juni 2026 | D46: pendapatan jasa | E46: 4110 | F46: {=IFERROR(INDEX(COA!$C$5:$C$59,MATCH(JURNAL!E46,COA!$B$5:$B$59,0)),"")} -> Pendapatan jasa | G46: 11207711 | J46: =IF(E46="","",COUNTIF($E$7:E46,E46)&E46) -> 34110
B47: 3 juni 2026 | D47: DTF | E47: 5070 | H47: 25000 | J47: =IF(E47="","",COUNTIF($E$7:E47,E47)&E47) -> 15070
B48: 3 juni 2026 | D48: BENSIN KIMKO | E48: 6000 | F48: {=IFERROR(INDEX(COA!$C$5:$C$59,MATCH(JURNAL!E48,COA!$B$5:$B$59,0)),"")} | H48: 20000 | J48: =IF(E48="","",COUNTIF($E$7:E48,E48)&E48) -> 26000
B49: 3 juni 2026 | D49: SUEDE ERASER | E49: 5030 | F49: {=IFERROR(INDEX(COA!$C$5:$C$59,MATCH(JURNAL!E49,COA!$B$5:$B$59,0)),"")} -> Hpp reguler | H49: 6912 | J49: =IF(E49="","",COUNTIF($E$7:E49,E49)&E49) -> 85030
B50: 3 juni 2026 | D50: CAT SERBAGUNA | E50: 5030 | F50: {=IFERROR(INDEX(COA!$C$5:$C$59,MATCH(JURNAL!E50,COA!$B$5:$B$59,0)),"")} -> Hpp reguler | H50: 28270 | J50: =IF(E50="","",COUNTIF($E$7:E50,E50)&E50) -> 95030
B51: 3 juni 2026 | D51: FOAM SHOES | E51: 5030 | F51: {=IFERROR(INDEX(COA!$C$5:$C$59,MATCH(JURNAL!E51,COA!$B$5:$B$59,0)),"")} -> Hpp reguler | H51: 43570 | J51: =IF(E51="","",COUNTIF($E$7:E51,E51)&E51) -> 105030
...

Sheet BUKU BESAR
B2: PT. TERANG GARAM SOLUSINDO | I2: AKUN | J2: 1104
B3: BUKU BESAR | H3: {=INDEX(Type,MATCH(J2,KODEAKUN,0))} -> Piutang
B4: PERIODE | H4: {=INDEX(SaldoNormal,MATCH(H3,Type,0))} -> Debet
B6: KODE AKUN | D6: =IF(J2="","PILIHAKUN",J2) -> 1104 | F6: SALDO AWAL | G6: =IF(H4="Debet",H6-H7,H7-H6) -> 0
B7: NAMA AKUN | D7: {=INDEX(Nama_Akun,MATCH(J2,KODEAKUN,0))} -> Piutang | F7: SALDO AKHIR | G7: =IF($H$4="Debet",G6+(SUM(E11:E90)-SUM(F11:F90)),G6+(SUM(F11:F90)-SUM(E11:E90))) -> 0 | H7: {=INDEX(COA_KREDIT,MATCH(J2,KODEAKUN,0))} -> 0
B9: Tanggal | C9: REF | D9: Keterangan | E9: Debet | F9: Kredit | G9: Saldo | I9: FILTER
H10: =IF(B11="",0,1) -> 0
A11: 1 | B11: {=IFERROR(INDEX(JU_Tanggal,MATCH(A11&$J$2,JU_BB,0)),"")} | C11: {=IFERROR(INDEX(JU_REF,MATCH(A11&$J$2,JU_BB,0)),"")} | D11: {=IFERROR(INDEX(JU_Keterangan,MATCH(A11&$J$2,JU_BB,0)),"")} | E11: {=IFERROR(INDEX(JU_Debet,MATCH(A11&$J$2,JU_BB,0)),"")} | F11: {=IFERROR(INDEX(JU_Kredit,MATCH(A11&$J$2,JU_BB,0)),"")} | G11: =IFERROR(IF($H$4="Debet",G6+E11-F11,G6+F11-E11),"") | H11: =IF(B11="",0,1) -> 0
A12: 2 | B12: {=IFERROR(INDEX(JU_Tanggal,MATCH(A12&$J$2,JU_BB,0)),"")} | C12: {=IFERROR(INDEX(JU_REF,MATCH(A12&$J$2,JU_BB,0)),"")} | D12: {=IFERROR(INDEX(JU_Keterangan,MATCH(A12&$J$2,JU_BB,0)),"")} | E12: {=IFERROR(INDEX(JU_Debet,MATCH(A12&$J$2,JU_BB,0)),"")} | F12: {=IFERROR(INDEX(JU_Kredit,MATCH(A12&$J$2,JU_BB,0)),"")} | G12: =IFERROR(IF($H$4="Debet",G11+E12-F12,G11+F12-E12),"") | H12: =IF(B12="",0,1) -> 0 | I12: beban
A13: 3 | B13: {=IFERROR(INDEX(JU_Tanggal,MATCH(A13&$J$2,JU_BB,0)),"")} | C13: {=IFERROR(INDEX(JU_REF,MATCH(A13&$J$2,JU_BB,0)),"")} | D13: {=IFERROR(INDEX(JU_Keterangan,MATCH(A13&$J$2,JU_BB,0)),"")} | E13: {=IFERROR(INDEX(JU_Debet,MATCH(A13&$J$2,JU_BB,0)),"")} | F13: {=IFERROR(INDEX(JU_Kredit,MATCH(A13&$J$2,JU_BB,0)),"")} | G13: =IFERROR(IF($H$4="Debet",G12+E13-F13,G12+F13-E13),"") | H13: =IF(B13="",0,1) -> 0 | I13: beban
A14: 4 | B14: {=IFERROR(INDEX(JU_Tanggal,MATCH(A14&$J$2,JU_BB,0)),"")} | C14: {=IFERROR(INDEX(JU_REF,MATCH(A14&$J$2,JU_BB,0)),"")} | D14: {=IFERROR(INDEX(JU_Keterangan,MATCH(A14&$J$2,JU_BB,0)),"")} | E14: {=IFERROR(INDEX(JU_Debet,MATCH(A14&$J$2,JU_BB,0)),"")} | F14: {=IFERROR(INDEX(JU_Kredit,MATCH(A14&$J$2,JU_BB,0)),"")} | G14: =IFERROR(IF($H$4="Debet",G13+E14-F14,G13+F14-E14),"") | H14: =IF(B14="",0,1) -> 0 | I14: beban
A15: 5 | B15: {=IFERROR(INDEX(JU_Tanggal,MATCH(A15&$J$2,JU_BB,0)),"")} | C15: {=IFERROR(INDEX(JU_REF,MATCH(A15&$J$2,JU_BB,0)),"")} | D15: {=IFERROR(INDEX(JU_Keterangan,MATCH(A15&$J$2,JU_BB,0)),"")} | E15: {=IFERROR(INDEX(JU_Debet,MATCH(A15&$J$2,JU_BB,0)),"")} | F15: {=IFERROR(INDEX(JU_Kredit,MATCH(A15&$J$2,JU_BB,0)),"")} | G15: =IFERROR(IF($H$4="Debet",G14+E15-F15,G14+F15-E15),"") | H15: =IF(B15="",0,1) -> 0 | I15: persediaan
A16: 6 | B16: {=IFERROR(INDEX(JU_Tanggal,MATCH(A16&$J$2,JU_BB,0)),"")} | C16: {=IFERROR(INDEX(JU_REF,MATCH(A16&$J$2,JU_BB,0)),"")} | D16: {=IFERROR(INDEX(JU_Keterangan,MATCH(A16&$J$2,JU_BB,0)),"")} | E16: {=IFERROR(INDEX(JU_Debet,MATCH(A16&$J$2,JU_BB,0)),"")} | F16: {=IFERROR(INDEX(JU_Kredit,MATCH(A16&$J$2,JU_BB,0)),"")} | G16: =IFERROR(IF($H$4="Debet",G15+E16-F16,G15+F16-E16),"") | H16: =IF(B16="",0,1) -> 0 | I16: piutang
A17: 7 | B17: {=IFERROR(INDEX(JU_Tanggal,MATCH(A17&$J$2,JU_BB,0)),"")} | C17: {=IFERROR(INDEX(JU_REF,MATCH(A17&$J$2,JU_BB,0)),"")} | D17: {=IFERROR(INDEX(JU_Keterangan,MATCH(A17&$J$2,JU_BB,0)),"")} | E17: {=IFERROR(INDEX(JU_Debet,MATCH(A17&$J$2,JU_BB,0)),"")} | F17: {=IFERROR(INDEX(JU_Kredit,MATCH(A17&$J$2,JU_BB,0)),"")} | G17: =IFERROR(IF($H$4="Debet",G16+E17-F17,G16+F17-E17),"") | H17: =IF(B17="",0,1) -> 0 | I17: pendapatan
A18: 8 | B18: {=IFERROR(INDEX(JU_Tanggal,MATCH(A18&$J$2,JU_BB,0)),"")} | C18: {=IFERROR(INDEX(JU_REF,MATCH(A18&$J$2,JU_BB,0)),"")} | D18: {=IFERROR(INDEX(JU_Keterangan,MATCH(A18&$J$2,JU_BB,0)),"")} | E18: {=IFERROR(INDEX(JU_Debet,MATCH(A18&$J$2,JU_BB,0)),"")} | F18: {=IFERROR(INDEX(JU_Kredit,MATCH(A18&$J$2,JU_BB,0)),"")} | G18: =IFERROR(IF($H$4="Debet",G17+E18-F18,G17+F18-E18),"") | H18: =IF(B18="",0,1) -> 0 | I18: pendapatan
A19: 9 | B19: {=IFERROR(INDEX(JU_Tanggal,MATCH(A19&$J$2,JU_BB,0)),"")} | C19: {=IFERROR(INDEX(JU_REF,MATCH(A19&$J$2,JU_BB,0)),"")} | D19: {=IFERROR(INDEX(JU_Keterangan,MATCH(A19&$J$2,JU_BB,0)),"")} | E19: {=IFERROR(INDEX(JU_Debet,MATCH(A19&$J$2,JU_BB,0)),"")} | F19: {=IFERROR(INDEX(JU_Kredit,MATCH(A19&$J$2,JU_BB,0)),"")} | G19: =IFERROR(IF($H$4="Debet",G18+E19-F19,G18+F19-E19),"") | H19: =IF(B19="",0,1) -> 0 | I19: beban
A20: 10 | B20: {=IFERROR(INDEX(JU_Tanggal,MATCH(A20&$J$2,JU_BB,0)),"")} | C20: {=IFERROR(INDEX(JU_REF,MATCH(A20&$J$2,JU_BB,0)),"")} | D20: {=IFERROR(INDEX(JU_Keterangan,MATCH(A20&$J$2,JU_BB,0)),"")} | E20: {=IFERROR(INDEX(JU_Debet,MATCH(A20&$J$2,JU_BB,0)),"")} | F20: {=IFERROR(INDEX(JU_Kredit,MATCH(A20&$J$2,JU_BB,0)),"")} | G20: =IFERROR(IF($H$4="Debet",G19+E20-F20,G19+F20-E20),"") | H20: =IF(B20="",0,1) -> 0 | I20: pendapatan
A21: 11 | B21: {=IFERROR(INDEX(JU_Tanggal,MATCH(A21&$J$2,JU_BB,0)),"")} | C21: {=IFERROR(INDEX(JU_REF,MATCH(A21&$J$2,JU_BB,0)),"")} | D21: {=IFERROR(INDEX(JU_Keterangan,MATCH(A21&$J$2,JU_BB,0)),"")} | E21: {=IFERROR(INDEX(JU_Debet,MATCH(A21&$J$2,JU_BB,0)),"")} | F21: {=IFERROR(INDEX(JU_Kredit,MATCH(A21&$J$2,JU_BB,0)),"")} | G21: =IFERROR(IF($H$4="Debet",G20+E21-F21,G20+F21-E21),"") | H21: =IF(B21="",0,1) -> 0 | I21: peralatan
A22: 12 | B22: {=IFERROR(INDEX(JU_Tanggal,MATCH(A22&$J$2,JU_BB,0)),"")} | C22: {=IFERROR(INDEX(JU_REF,MATCH(A22&$J$2,JU_BB,0)),"")} | D22: {=IFERROR(INDEX(JU_Keterangan,MATCH(A22&$J$2,JU_BB,0)),"")} | E22: {=IFERROR(INDEX(JU_Debet,MATCH(A22&$J$2,JU_BB,0)),"")} | F22: {=IFERROR(INDEX(JU_Kredit,MATCH(A22&$J$2,JU_BB,0)),"")} | G22: =IFERROR(IF($H$4="Debet",G21+E22-F22,G21+F22-E22),"") | H22: =IF(B22="",0,1) -> 0 | I22: peralatan
A23: 13 | B23: {=IFERROR(INDEX(JU_Tanggal,MATCH(A23&$J$2,JU_BB,0)),"")} | C23: {=IFERROR(INDEX(JU_REF,MATCH(A23&$J$2,JU_BB,0)),"")} | D23: {=IFERROR(INDEX(JU_Keterangan,MATCH(A23&$J$2,JU_BB,0)),"")} | E23: {=IFERROR(INDEX(JU_Debet,MATCH(A23&$J$2,JU_BB,0)),"")} | F23: {=IFERROR(INDEX(JU_Kredit,MATCH(A23&$J$2,JU_BB,0)),"")} | G23: =IFERROR(IF($H$4="Debet",G22+E23-F23,G22+F23-E23),"") | H23: =IF(B23="",0,1) -> 0 | I23: pendapatan
... A26: 16 | B26: {=IFERROR(INDEX(JU_Tanggal,MATCH(A26&$J$2,JU_BB,0)),"")} | C26: {=IFERROR(INDEX(JU_REF,MATCH(A26&$J$2,JU_BB,0)),"")} | D26: {=IFERROR(INDEX(JU_Keterangan,MATCH(A26&$J$2,JU_BB,0)),"")} | E26: {=IFERROR(INDEX(JU_Debet,MATCH(A26&$J$2,JU_BB,0)),"")} | F26: {=IFERROR(INDEX(JU_Kredit,MATCH(A26&$J$2,JU_BB,0)),"")} | G26: =IFERROR(IF($H$4="Debet",G25+E26-F26,G25+F26-E26),"") | H26: =IF(B26="",0,1) -> 0 | I26: pendapatan
A27: =A26+1 -> 17 | B27: {=IFERROR(INDEX(JU_Tanggal,MATCH(A27&$J$2,JU_BB,0)),"")} | C27: {=IFERROR(INDEX(JU_REF,MATCH(A27&$J$2,JU_BB,0)),"")} | D27: {=IFERROR(INDEX(JU_Keterangan,MATCH(A27&$J$2,JU_BB,0)),"")} | E27: {=IFERROR(INDEX(JU_Debet,MATCH(A27&$J$2,JU_BB,0)),"")} | F27: {=IFERROR(INDEX(JU_Kredit,MATCH(A27&$J$2,JU_BB,0)),"")} | G27: =IFERROR(IF($H$4="Debet",G26+E27-F27,G26+F27-E27),"") | H27: =IF(B27="",0,1) -> 0 | I27: beban
A28: =A27+1 -> 18 | B28: {=IFERROR(INDEX(JU_Tanggal,MATCH(A28&$J$2,JU_BB,0)),"")} | C28: {=IFERROR(INDEX(JU_REF,MATCH(A28&$J$2,JU_BB,0)),"")} | D28: {=IFERROR(INDEX(JU_Keterangan,MATCH(A28&$J$2,JU_BB,0)),"")} | E28: {=IFERROR(INDEX(JU_Debet,MATCH(A28&$J$2,JU_BB,0)),"")} | F28: {=IFERROR(INDEX(JU_Kredit,MATCH(A28&$J$2,JU_BB,0)),"")} | G28: =IFERROR(IF($H$4="Debet",G27+E28-F28,G27+F28-E28),"") | H28: =IF(B28="",0,1) -> 0 | I28: persediaan
A29: =A28+1 -> 19 | B29: {=IFERROR(INDEX(JU_Tanggal,MATCH(A29&$J$2,JU_BB,0)),"")} | C29: {=IFERROR(INDEX(JU_REF,MATCH(A29&$J$2,JU_BB,0)),"")} | D29: {=IFERROR(INDEX(JU_Keterangan,MATCH(A29&$J$2,JU_BB,0)),"")} | E29: {=IFERROR(INDEX(JU_Debet,MATCH(A29&$J$2,JU_BB,0)),"")} | F29: {=IFERROR(INDEX(JU_Kredit,MATCH(A29&$J$2,JU_BB,0)),"")} | G29: =IFERROR(IF($H$4="Debet",G28+E29-F29,G28+F29-E29),"") | H29: =IF(B29="",0,1) -> 0 | I29: pendapatan
A30: =A29+1 -> 20 | B30: {=IFERROR(INDEX(JU_Tanggal,MATCH(A30&$J$2,JU_BB,0)),"")} | C30: {=IFERROR(INDEX(JU_REF,MATCH(A30&$J$2,JU_BB,0)),"")} | D30: {=IFERROR(INDEX(JU_Keterangan,MATCH(A30&$J$2,JU_BB,0)),"")} | E30: {=IFERROR(INDEX(JU_Debet,MATCH(A30&$J$2,JU_BB,0)),"")} | F30: {=IFERROR(INDEX(JU_Kredit,MATCH(A30&$J$2,JU_BB,0)),"")} | G30: =IFERROR(IF($H$4="Debet",G29+E30-F30,G29+F30-E30),"") | H30: =IF(B30="",0,1) -> 0 | I30: pendapatan
A31: =A30+1 -> 21 | B31: {=IFERROR(INDEX(JU_Tanggal,MATCH(A31&$J$2,JU_BB,0)),"")} | C31: {=IFERROR(INDEX(JU_REF,MATCH(A31&$J$2,JU_BB,0)),"")} | D31: {=IFERROR(INDEX(JU_Keterangan,MATCH(A31&$J$2,JU_BB,0)),"")} | E31: {=IFERROR(INDEX(JU_Debet,MATCH(A31&$J$2,JU_BB,0)),"")} | F31: {=IFERROR(INDEX(JU_Kredit,MATCH(A31&$J$2,JU_BB,0)),"")} | G31: =IFERROR(IF($H$4="Debet",G30+E31-F31,G30+F31-E31),"") | H31: =IF(B31="",0,1) -> 0 | I31: pendapatan
A32: =A31+1 -> 22 | B32: {=IFERROR(INDEX(JU_Tanggal,MATCH(A32&$J$2,JU_BB,0)),"")} | C32: {=IFERROR(INDEX(JU_REF,MATCH(A32&$J$2,JU_BB,0)),"")} | D32: {=IFERROR(INDEX(JU_Keterangan,MATCH(A32&$J$2,JU_BB,0)),"")} | E32: {=IFERROR(INDEX(JU_Debet,MATCH(A32&$J$2,JU_BB,0)),"")} | F32: {=IFERROR(INDEX(JU_Kredit,MATCH(A32&$J$2,JU_BB,0)),"")} | G32: =IFERROR(IF($H$4="Debet",G31+E32-F32,G31+F32-E32),"") | H32: =IF(B32="",0,1) -> 0 | I32: beban
A33: =A32+1 -> 23 | B33: {=IFERROR(INDEX(JU_Tanggal,MATCH(A33&$J$2,JU_BB,0)),"")} | C33: {=IFERROR(INDEX(JU_REF,MATCH(A33&$J$2,JU_BB,0)),"")} | D33: {=IFERROR(INDEX(JU_Keterangan,MATCH(A33&$J$2,JU_BB,0)),"")} | E33: {=IFERROR(INDEX(JU_Debet,MATCH(A33&$J$2,JU_BB,0)),"")} | F33: {=IFERROR(INDEX(JU_Kredit,MATCH(A33&$J$2,JU_BB,0)),"")} | G33: =IFERROR(IF($H$4="Debet",G32+E33-F33,G32+F33-E33),"") | H33: =IF(B33="",0,1) -> 0 | I33: pendapatan
A34: =A33+1 -> 24 | B34: {=IFERROR(INDEX(JU_Tanggal,MATCH(A34&$J$2,JU_BB,0)),"")} | C34: {=IFERROR(INDEX(JU_REF,MATCH(A34&$J$2,JU_BB,0)),"")} | D34: {=IFERROR(INDEX(JU_Keterangan,MATCH(A34&$J$2,JU_BB,0)),"")} | E34: {=IFERROR(INDEX(JU_Debet,MATCH(A34&$J$2,JU_BB,0)),"")} | F34: {=IFERROR(INDEX(JU_Kredit,MATCH(A34&$J$2,JU_BB,0)),"")} | G34: =IFERROR(IF($H$4="Debet",G33+E34-F34,G33+F34-E34),"") | H34: =IF(B34="",0,1) -> 0 | I34: beban
A35: =A34+1 -> 25 | B35: {=IFERROR(INDEX(JU_Tanggal,MATCH(A35&$J$2,JU_BB,0)),"")} | C35: {=IFERROR(INDEX(JU_REF,MATCH(A35&$J$2,JU_BB,0)),"")} | D35: {=IFERROR(INDEX(JU_Keterangan,MATCH(A35&$J$2,JU_BB,0)),"")} | E35: {=IFERROR(INDEX(JU_Debet,MATCH(A35&$J$2,JU_BB,0)),"")} | F35: {=IFERROR(INDEX(JU_Kredit,MATCH(A35&$J$2,JU_BB,0)),"")} | G35: =IFERROR(IF($H$4="Debet",G34+E35-F35,G34+F35-E35),"") | H35: =IF(B35="",0,1) -> 0 | I35: pendapatan
A36: =A35+1 -> 26 | B36: {=IFERROR(INDEX(JU_Tanggal,MATCH(A36&$J$2,JU_BB,0)),"")} | C36: {=IFERROR(INDEX(JU_REF,MATCH(A36&$J$2,JU_BB,0)),"")} | D36: {=IFERROR(INDEX(JU_Keterangan,MATCH(A36&$J$2,JU_BB,0)),"")} | E36: {=IFERROR(INDEX(JU_Debet,MATCH(A36&$J$2,JU_BB,0)),"")} | F36: {=IFERROR(INDEX(JU_Kredit,MATCH(A36&$J$2,JU_BB,0)),"")} | G36: =IFERROR(IF($H$4="Debet",G35+E36-F36,G35+F36-E36),"") | H36: =IF(B36="",0,1) -> 0 | I36: pendapatan
A37: =A36+1 -> 27 | B37: {=IFERROR(INDEX(JU_Tanggal,MATCH(A37&$J$2,JU_BB,0)),"")} | C37: {=IFERROR(INDEX(JU_REF,MATCH(A37&$J$2,JU_BB,0)),"")} | D37: {=IFERROR(INDEX(JU_Keterangan,MATCH(A37&$J$2,JU_BB,0)),"")} | E37: {=IFERROR(INDEX(JU_Debet,MATCH(A37&$J$2,JU_BB,0)),"")} | F37: {=IFERROR(INDEX(JU_Kredit,MATCH(A37&$J$2,JU_BB,0)),"")} | G37: =IFERROR(IF($H$4="Debet",G36+E37-F37,G36+F37-E37),"") | H37: =IF(B37="",0,1) -> 0 | I37: persediaan
A38: =A37+1 -> 28 | B38: {=IFERROR(INDEX(JU_Tanggal,MATCH(A38&$J$2,JU_BB,0)),"")} | C38: {=IFERROR(INDEX(JU_REF,MATCH(A38&$J$2,JU_BB,0)),"")} | D38: {=IFERROR(INDEX(JU_Keterangan,MATCH(A38&$J$2,JU_BB,0)),"")} | E38: {=IFERROR(INDEX(JU_Debet,MATCH(A38&$J$2,JU_BB,0)),"")} | F38: {=IFERROR(INDEX(JU_Kredit,MATCH(A38&$J$2,JU_BB,0)),"")} | G38: =IFERROR(IF($H$4="Debet",G37+E38-F38,G37+F38-E38),"") | H38: =IF(B38="",0,1) -> 0 | I38: beban
... A73: =A72+1 -> 63 | B73: {=IFERROR(INDEX(JU_Tanggal,MATCH(A73&$J$2,JU_BB,0)),"")} | C73: {=IFERROR(INDEX(JU_REF,MATCH(A73&$J$2,JU_BB,0)),"")} | D73: {=IFERROR(INDEX(JU_Keterangan,MATCH(A73&$J$2,JU_BB,0)),"")} | E73: {=IFERROR(INDEX(JU_Debet,MATCH(A73&$J$2,JU_BB,0)),"")} | F73: {=IFERROR(INDEX(JU_Kredit,MATCH(A73&$J$2,JU_BB,0)),"")} | G73: =IFERROR(IF($H$4="Debet",G72+E73-F73,G72+F73-E73),"") | H73: =IF(B73="",0,1) -> 0 | I73: beban
B74: {=IFERROR(INDEX(JU_Tanggal,MATCH(A74&$J$2,JU_BB,0)),"")} | C74: {=IFERROR(INDEX(JU_REF,MATCH(A74&$J$2,JU_BB,0)),"")} | D74: {=IFERROR(INDEX(JU_Keterangan,MATCH(A74&$J$2,JU_BB,0)),"")} | E74: {=IFERROR(INDEX(JU_Debet,MATCH(A74&$J$2,JU_BB,0)),"")} | F74: {=IFERROR(INDEX(JU_Kredit,MATCH(A74&$J$2,JU_BB,0)),"")} | H74: =IF(B74="",0,1) -> 0
B75: {=IFERROR(INDEX(JU_Tanggal,MATCH(A75&$J$2,JU_BB,0)),"")} | C75: {=IFERROR(INDEX(JU_REF,MATCH(A75&$J$2,JU_BB,0)),"")} | D75: {=IFERROR(INDEX(JU_Keterangan,MATCH(A75&$J$2,JU_BB,0)),"")} | E75: {=IFERROR(INDEX(JU_Debet,MATCH(A75&$J$2,JU_BB,0)),"")} | F75: {=IFERROR(INDEX(JU_Kredit,MATCH(A75&$J$2,JU_BB,0)),"")} | H75: =IF(B75="",0,1) -> 0
B76: {=IFERROR(INDEX(JU_Tanggal,MATCH(A76&$J$2,JU_BB,0)),"")} | C76: {=IFERROR(INDEX(JU_REF,MATCH(A76&$J$2,JU_BB,0)),"")} | D76: {=IFERROR(INDEX(JU_Keterangan,MATCH(A76&$J$2,JU_BB,0)),"")} | E76: {=IFERROR(INDEX(JU_Debet,MATCH(A76&$J$2,JU_BB,0)),"")} | F76: {=IFERROR(INDEX(JU_Kredit,MATCH(A76&$J$2,JU_BB,0)),"")} | H76: =IF(B76="",0,1) -> 0
B77: {=IFERROR(INDEX(JU_Tanggal,MATCH(A77&$J$2,JU_BB,0)),"")} | C77: {=IFERROR(INDEX(JU_REF,MATCH(A77&$J$2,JU_BB,0)),"")} | D77: {=IFERROR(INDEX(JU_Keterangan,MATCH(A77&$J$2,JU_BB,0)),"")} | E77: {=IFERROR(INDEX(JU_Debet,MATCH(A77&$J$2,JU_BB,0)),"")} | F77: {=IFERROR(INDEX(JU_Kredit,MATCH(A77&$J$2,JU_BB,0)),"")} | H77: =IF(B77="",0,1) -> 0
B78: {=IFERROR(INDEX(JU_Tanggal,MATCH(A78&$J$2,JU_BB,0)),"")} | C78: {=IFERROR(INDEX(JU_REF,MATCH(A78&$J$2,JU_BB,0)),"")} | D78: {=IFERROR(INDEX(JU_Keterangan,MATCH(A78&$J$2,JU_BB,0)),"")} | E78: {=IFERROR(INDEX(JU_Debet,MATCH(A78&$J$2,JU_BB,0)),"")} | F78: {=IFERROR(INDEX(JU_Kredit,MATCH(A78&$J$2,JU_BB,0)),"")} | H78: =IF(B78="",0,1) -> 0
B79: {=IFERROR(INDEX(JU_Tanggal,MATCH(A79&$J$2,JU_BB,0)),"")} | C79: {=IFERROR(INDEX(JU_REF,MATCH(A79&$J$2,JU_BB,0)),"")} | D79: {=IFERROR(INDEX(JU_Keterangan,MATCH(A79&$J$2,JU_BB,0)),"")} | E79: {=IFERROR(INDEX(JU_Debet,MATCH(A79&$J$2,JU_BB,0)),"")} | F79: {=IFERROR(INDEX(JU_Kredit,MATCH(A79&$J$2,JU_BB,0)),"")} | H79: =IF(B79="",0,1) -> 0
...

Sheet NRL
B2: ='BUKU BESAR'!B2:F2 -> PT. TERANG GARAM SOLUSINDO
B3: NERACA LAJUR
B4: ='BUKU BESAR'!B4:F4 -> PERIODE
B6: KODE | C6: NAMA AKUN | E6: POS | F6: SN | G6: SALDO AWAL | I6: PERGERAKAN | K6: SALDO AKHIR | M6: LABA RUGI | O6: NERACA
G7: DEBET | H7: KREDIT | I7: DEBET | J7: KREDIT | K7: DEBET | L7: Kredit | M7: DEBET | N7: KREDIT | O7: DEBET | P7: KREDIT
B8: =IF(COA!B5="","",COA!B5) -> 1101 | C8: =IFERROR(INDEX(Nama_Akun,MATCH(B8,KODEAKUN,0)),"") -> Kas | D8: {=IFERROR(INDEX(Type,MATCH(B8,KODEAKUN,0)),"")} -> Kas | E8: {=INDEX(Posisi,MATCH(D8,Type,0))} -> Neraca | F8: {=IFERROR(INDEX(SaldoNormal,MATCH(D8,Type,)),"")} -> Debet | G8: {=IFERROR(INDEX(COA_DEBET,MATCH(B8,KODEAKUN,0)),"")} -> 0 | H8: {=IFERROR(INDEX(COA_KREDIT,MATCH(B8,KODEAKUN,0)),"")} -> 0 | I8: =IF(B8="","",SUMIF(JU_Kodeakun,B8,JU_Debet)) -> 0 | J8: =IF(B8="","",SUMIF(JU_Kodeakun,B8,JU_Kredit)) -> 0 | K8: =IF(F8="Debet",G8+I8-H8-J8,0) -> 0 | L8: =IF(F8="Kredit",H8+J8-G8-I8,0) -> 0 | M8: =IF(E8="Laba Rugi",K8,0) -> 0 | N8: =IF(E8="Laba Rugi",L8,0) -> 0 | O8: =IF(E8="Neraca",K8,0) -> 0 | P8: =IF(E8="Neraca",L8,0) -> 0 | R8: FILTER
B9: =IF(COA!B6="","",COA!B6) -> 1102 | C9: {=IFERROR(INDEX(Nama_Akun,MATCH(B9,KODEAKUN,0)),"")} -> Kas Di Bank | D9: {=IFERROR(INDEX(Type,MATCH(B9,KODEAKUN,0)),"")} -> Kas Di Bank | E9: {=INDEX(Posisi,MATCH(D9,Type,0))} -> Neraca | F9: {=IFERROR(INDEX(SaldoNormal,MATCH(D9,Type,)),"")} -> Debet | G9: {=IFERROR(INDEX(COA_DEBET,MATCH(B9,KODEAKUN,0)),"")} -> 0 | H9: {=IFERROR(INDEX(COA_KREDIT,MATCH(B9,KODEAKUN,0)),"")} -> 0 | I9: =IF(B9="","",SUMIF(JU_Kodeakun,B9,JU_Debet)) -> 0 | J9: =IF(B9="","",SUMIF(JU_Kodeakun,B9,JU_Kredit)) -> 0 | K9: =IF(F9="Debet",G9+I9-H9-J9,0) -> 0 | L9: =IF(F9="Kredit",H9+J9-G9-I9,0) -> 0 | M9: =IF(E9="Laba Rugi",K9,0) -> 0 | N9: =IF(E9="Laba Rugi",L9,0) -> 0 | O9: =IF(E9="Neraca",K9,0) -> 0 | P9: =IF(E9="Neraca",L9,0) -> 0 | R9: =IF(AND(G9=0,H9=0,I9=0,J9=0,K9=0,L9=0,M9=0,N9=0,O9=0,P9=0),0,1) -> 0
B10: =IF(COA!B7="","",COA!B7) -> 1103 | C10: {=IFERROR(INDEX(Nama_Akun,MATCH(B10,KODEAKUN,0)),"")} -> Petty Cash | D10: {=IFERROR(INDEX(Type,MATCH(B10,KODEAKUN,0)),"")} -> Petty Cash | E10: {=INDEX(Posisi,MATCH(D10,Type,0))} -> Neraca | F10: {=IFERROR(INDEX(SaldoNormal,MATCH(D10,Type,)),"")} -> Debet | G10: {=IFERROR(INDEX(COA_DEBET,MATCH(B10,KODEAKUN,0)),"")} -> 0 | H10: {=IFERROR(INDEX(COA_KREDIT,MATCH(B10,KODEAKUN,0)),"")} -> 0 | I10: =IF(B10="","",SUMIF(JU_Kodeakun,B10,JU_Debet)) -> 0 | J10: =IF(B10="","",SUMIF(JU_Kodeakun,B10,JU_Kredit)) -> 0 | K10: =IF(F10="Debet",G10+I10-H10-J10,0) -> 0 | L10: =IF(F10="Kredit",H10+J10-G10-I10,0) -> 0 | M10: =IF(E10="Laba Rugi",K10,0) -> 0 | N10: =IF(E10="Laba Rugi",L10,0) -> 0 | O10: =IF(E10="Neraca",K10,0) -> 0 | P10: =IF(E10="Neraca",L10,0) -> 0 | R10: =IF(AND(G10=0,H10=0,I10=0,J10=0,K10=0,L10=0,M10=0,N10=0,O10=0,P10=0),0,1) -> 0
B11: =IF(COA!B8="","",COA!B8) -> 1104 | C11: {=IFERROR(INDEX(Nama_Akun,MATCH(B11,KODEAKUN,0)),"")} -> Piutang | D11: {=IFERROR(INDEX(Type,MATCH(B11,KODEAKUN,0)),"")} -> Piutang | E11: {=INDEX(Posisi,MATCH(D11,Type,0))} -> Neraca | F11: {=IFERROR(INDEX(SaldoNormal,MATCH(D11,Type,)),"")} -> Debet | G11: {=IFERROR(INDEX(COA_DEBET,MATCH(B11,KODEAKUN,0)),"")} -> 0 | H11: {=IFERROR(INDEX(COA_KREDIT,MATCH(B11,KODEAKUN,0)),"")} -> 0 | I11: =IF(B11="","",SUMIF(JU_Kodeakun,B11,JU_Debet)) -> 0 | J11: =IF(B11="","",SUMIF(JU_Kodeakun,B11,JU_Kredit)) -> 0 | K11: =IF(F11="Debet",G11+I11-H11-J11,0) -> 0 | L11: =IF(F11="Kredit",H11+J11-G11-I11,0) -> 0 | M11: =IF(E11="Laba Rugi",K11,0) -> 0 | N11: =IF(E11="Laba Rugi",L11,0) -> 0 | O11: =IF(E11="Neraca",K11,0) -> 0 | P11: =IF(E11="Neraca",L11,0) -> 0 | R11: =IF(AND(G12=0,H12=0,I12=0,J12=0,K12=0,L12=0,M12=0,N12=0,O12=0,P12=0),0,1) -> 0
B12: =IF(COA!B9="","",COA!B9) -> 1105 | C12: {=IFERROR(INDEX(Nama_Akun,MATCH(B12,KODEAKUN,0)),"")} -> Persediaan | D12: {=IFERROR(INDEX(Type,MATCH(B12,KODEAKUN,0)),"")} -> Persediaan | E12: {=INDEX(Posisi,MATCH(D12,Type,0))} -> Neraca | F12: {=IFERROR(INDEX(SaldoNormal,MATCH(D12,Type,)),"")} -> Debet | G12: {=IFERROR(INDEX(COA_DEBET,MATCH(B12,KODEAKUN,0)),"")} -> 0 | H12: {=IFERROR(INDEX(COA_KREDIT,MATCH(B12,KODEAKUN,0)),"")} -> 0 | I12: =IF(B12="","",SUMIF(JU_Kodeakun,B12,JU_Debet)) -> 0 | J12: =IF(B12="","",SUMIF(JU_Kodeakun,B12,JU_Kredit)) -> 0 | K12: =IF(F12="Debet",G12+I12-H12-J12,0) -> 0 | L12: =IF(F12="Kredit",H12+J12-G12-I12,0) -> 0 | M12: =IF(E12="Laba Rugi",K12,0) -> 0 | N12: =IF(E12="Laba Rugi",L12,0) -> 0 | O12: =IF(E12="Neraca",K12,0) -> 0 | P12: =IF(E12="Neraca",L12,0) -> 0 | R12: =IF(AND(G13=0,H13=0,I13=0,J13=0,K13=0,L13=0,M13=0,N13=0,O13=0,P13=0),0,1) -> 0
B13: =IF(COA!B10="","",COA!B10) -> 1106 | C13: {=IFERROR(INDEX(Nama_Akun,MATCH(B13,KODEAKUN,0)),"")} -> Perlengkapan | D13: {=IFERROR(INDEX(Type,MATCH(B13,KODEAKUN,0)),"")} -> Perlengkapan | E13: {=INDEX(Posisi,MATCH(D13,Type,0))} -> Neraca | F13: {=IFERROR(INDEX(SaldoNormal,MATCH(D13,Type,)),"")} -> Debet | G13: {=IFERROR(INDEX(COA_DEBET,MATCH(B13,KODEAKUN,0)),"")} -> 0 | H13: {=IFERROR(INDEX(COA_KREDIT,MATCH(B13,KODEAKUN,0)),"")} -> 0 | I13: =IF(B13="","",SUMIF(JU_Kodeakun,B13,JU_Debet)) -> 0 | J13: =IF(B13="","",SUMIF(JU_Kodeakun,B13,JU_Kredit)) -> 0 | K13: =IF(F13="Debet",G13+I13-H13-J13,0) -> 0 | L13: =IF(F13="Kredit",H13+J13-G13-I13,0) -> 0 | M13: =IF(E13="Laba Rugi",K13,0) -> 0 | N13: =IF(E13="Laba Rugi",L13,0) -> 0 | O13: =IF(E13="Neraca",K13,0) -> 0 | P13: =IF(E13="Neraca",L13,0) -> 0 | R13: =IF(AND(G14=0,H14=0,I14=0,J14=0,K14=0,L14=0,M14=0,N14=0,O14=0,P14=0),0,1) -> 1
B14: =IF(COA!B11="","",COA!B11) -> 1201 | C14: {=IFERROR(INDEX(Nama_Akun,MATCH(B14,KODEAKUN,0)),"")} -> Peralatan | D14: {=IFERROR(INDEX(Type,MATCH(B14,KODEAKUN,0)),"")} -> Peralatan | E14: {=INDEX(Posisi,MATCH(D14,Type,0))} -> Neraca | F14: {=IFERROR(INDEX(SaldoNormal,MATCH(D14,Type,)),"")} -> Debet | G14: {=IFERROR(INDEX(COA_DEBET,MATCH(B14,KODEAKUN,0)),"")} -> 0 | H14: {=IFERROR(INDEX(COA_KREDIT,MATCH(B14,KODEAKUN,0)),"")} -> 0 | I14: =IF(B14="","",SUMIF(JU_Kodeakun,B14,JU_Debet)) -> 0 | J14: =IF(B14="","",SUMIF(JU_Kodeakun,B14,JU_Kredit)) -> 515685 | K14: =IF(F14="Debet",G14+I14-H14-J14,0) -> -515685 | L14: =IF(F14="Kredit",H14+J14-G14-I14,0) -> 0 | M14: =IF(E14="Laba Rugi",K14,0) -> 0 | N14: =IF(E14="Laba Rugi",L14,0) -> 0 | O14: =IF(E14="Neraca",K14,0) -> -515685 | P14: =IF(E14="Neraca",L14,0) -> 0 | R14: =IF(AND(G15=0,H15=0,I15=0,J15=0,K15=0,L15=0,M15=0,N15=0,O15=0,P15=0),0,1) -> 0
B15: =IF(COA!B12="","",COA!B12) -> 1202 | C15: {=IFERROR(INDEX(Nama_Akun,MATCH(B15,KODEAKUN,0)),"")} -> Akumulasi Penyusutan Peralatan | D15: {=IFERROR(INDEX(Type,MATCH(B15,KODEAKUN,0)),"")} -> Akumulasi Penyusutan Peralatan | E15: {=INDEX(Posisi,MATCH(D15,Type,0))} -> Neraca | F15: {=IFERROR(INDEX(SaldoNormal,MATCH(D15,Type,)),"")} -> Kredit | G15: {=IFERROR(INDEX(COA_DEBET,MATCH(B15,KODEAKUN,0)),"")} -> 0 | H15: {=IFERROR(INDEX(COA_KREDIT,MATCH(B15,KODEAKUN,0)),"")} -> 0 | I15: =IF(B15="","",SUMIF(JU_Kodeakun,B15,JU_Debet)) -> 0 | J15: =IF(B15="","",SUMIF(JU_Kodeakun,B15,JU_Kredit)) -> 0 | K15: =IF(F15="Debet",G15+I15-H15-J15,0) -> 0 | L15: =IF(F15="Kredit",H15+J15-G15-I15,0) -> 0 | M15: =IF(E15="Laba Rugi",K15,0) -> 0 | N15: =IF(E15="Laba Rugi",L15,0) -> 0 | O15: =IF(E15="Neraca",K15,0) -> 0 | P15: =IF(E15="Neraca",L15,0) -> 0 | R15: =IF(AND(G16=0,H16=0,I16=0,J16=0,K16=0,L16=0,M16=0,N16=0,O16=0,P16=0),0,1) -> 0
B16: =IF(COA!B13="","",COA!B13) -> 2110 | C16: {=IFERROR(INDEX(Nama_Akun,MATCH(B16,KODEAKUN,0)),"")} -> Utang | D16: {=IFERROR(INDEX(Type,MATCH(B16,KODEAKUN,0)),"")} -> Utang | E16: {=INDEX(Posisi,MATCH(D16,Type,0))} -> Neraca | F16: {=IFERROR(INDEX(SaldoNormal,MATCH(D16,Type,)),"")} -> Kredit | G16: {=IFERROR(INDEX(COA_DEBET,MATCH(B16,KODEAKUN,0)),"")} -> 0 | H16: {=IFERROR(INDEX(COA_KREDIT,MATCH(B16,KODEAKUN,0)),"")} -> 0 | I16: =IF(B16="","",SUMIF(JU_Kodeakun,B16,JU_Debet)) -> 0 | J16: =IF(B16="","",SUMIF(JU_Kodeakun,B16,JU_Kredit)) -> 0 | K16: =IF(F16="Debet",G16+I16-H16-J16,0) -> 0 | L16: =IF(F16="Kredit",H16+J16-G16-I16,0) -> 0 | M16: =IF(E16="Laba Rugi",K16,0) -> 0 | N16: =IF(E16="Laba Rugi",L16,0) -> 0 | O16: =IF(E16="Neraca",K16,0) -> 0 | P16: =IF(E16="Neraca",L16,0) -> 0 | R16: =IF(AND(G17=0,H17=0,I17=0,J17=0,K17=0,L17=0,M17=0,N17=0,O17=0,P17=0),0,1) -> 1
B17: =IF(COA!B14="","",COA!B14) -> 2120 | C17: {=IFERROR(INDEX(Nama_Akun,MATCH(B17,KODEAKUN,0)),"")} -> Utang Gaji | D17: {=IFERROR(INDEX(Type,MATCH(B17,KODEAKUN,0)),"")} -> Utang Gaji | E17: {=INDEX(Posisi,MATCH(D17,Type,0))} -> Neraca | F17: {=IFERROR(INDEX(SaldoNormal,MATCH(D17,Type,)),"")} -> Kredit | G17: {=IFERROR(INDEX(COA_DEBET,MATCH(B17,KODEAKUN,0)),"")} -> 0 | H17: {=IFERROR(INDEX(COA_KREDIT,MATCH(B17,KODEAKUN,0)),"")} -> 0 | I17: =IF(B17="","",SUMIF(JU_Kodeakun,B17,JU_Debet)) -> 0 | J17: =IF(B17="","",SUMIF(JU_Kodeakun,B17,JU_Kredit)) -> 105901167 | K17: =IF(F17="Debet",G17+I17-H17-J17,0) -> 0 | L17: =IF(F17="Kredit",H17+J17-G17-I17,0) -> 105901167 | M17: =IF(E17="Laba Rugi",K17,0) -> 0 | N17: =IF(E17="Laba Rugi",L17,0) -> 0 | O17: =IF(E17="Neraca",K17,0) -> 0 | P17: =IF(E17="Neraca",L17,0) -> 105901167 | R17: =IF(AND(G18=0,H18=0,I18=0,J18=0,K18=0,L18=0,M18=0,N18=0,O18=0,P18=0),0,1) -> 0
B18: =IF(COA!B15="","",COA!B15) -> 2130 | C18: {=IFERROR(INDEX(Nama_Akun,MATCH(B18,KODEAKUN,0)),"")} -> utang pajak | D18: {=IFERROR(INDEX(Type,MATCH(B18,KODEAKUN,0)),"")} -> utang pajak | E18: {=INDEX(Posisi,MATCH(D18,Type,0))} -> Neraca | F18: {=IFERROR(INDEX(SaldoNormal,MATCH(D18,Type,)),"")} -> Kredit | G18: {=IFERROR(INDEX(COA_DEBET,MATCH(B18,KODEAKUN,0)),"")} -> 0 | H18: {=IFERROR(INDEX(COA_KREDIT,MATCH(B18,KODEAKUN,0)),"")} -> 0 | I18: =IF(B18="","",SUMIF(JU_Kodeakun,B18,JU_Debet)) -> 0 | J18: =IF(B18="","",SUMIF(JU_Kodeakun,B18,JU_Kredit)) -> 0 | K18: =IF(F18="Debet",G18+I18-H18-J18,0) -> 0 | L18: =IF(F18="Kredit",H18+J18-G18-I18,0) -> 0 | M18: =IF(E18="Laba Rugi",K18,0) -> 0 | N18: =IF(E18="Laba Rugi",L18,0) -> 0 | O18: =IF(E18="Neraca",K18,0) -> 0 | P18: =IF(E18="Neraca",L18,0) -> 0 | R18: =IF(AND(G19=0,H19=0,I19=0,J19=0,K19=0,L19=0,M19=0,N19=0,O19=0,P19=0),0,1) -> 0
B19: =IF(COA!B16="","",COA!B16) -> 2140 | C19: {=IFERROR(INDEX(Nama_Akun,MATCH(B19,KODEAKUN,0)),"")} -> utang pdam | D19: {=IFERROR(INDEX(Type,MATCH(B19,KODEAKUN,0)),"")} -> utang pdam | E19: {=INDEX(Posisi,MATCH(D19,Type,0))} -> Neraca | F19: {=IFERROR(INDEX(SaldoNormal,MATCH(D19,Type,)),"")} -> Kredit | G19: {=IFERROR(INDEX(COA_DEBET,MATCH(B19,KODEAKUN,0)),"")} -> 0 | H19: {=IFERROR(INDEX(COA_KREDIT,MATCH(B19,KODEAKUN,0)),"")} -> 0 | I19: =IF(B19="","",SUMIF(JU_Kodeakun,B19,JU_Debet)) -> 0 | J19: =IF(B19="","",SUMIF(JU_Kodeakun,B19,JU_Kredit)) -> 0 | K19: =IF(F19="Debet",G19+I19-H19-J19,0) -> 0 | L19: =IF(F19="Kredit",H19+J19-G19-I19,0) -> 0 | M19: =IF(E19="Laba Rugi",K19,0) -> 0 | N19: =IF(E19="Laba Rugi",L19,0) -> 0 | O19: =IF(E19="Neraca",K19,0) -> 0 | P19: =IF(E19="Neraca",L19,0) -> 0 | R19: =IF(AND(G20=0,H20=0,I20=0,J20=0,K20=0,L20=0,M20=0,N20=0,O20=0,P20=0),0,1) -> 0
B20: =IF(COA!B17="","",COA!B17) -> 2150 | C20: {=IFERROR(INDEX(Nama_Akun,MATCH(B20,KODEAKUN,0)),"")} -> utang jne | D20: {=IFERROR(INDEX(Type,MATCH(B20,KODEAKUN,0)),"")} -> utang jne | E20: {=INDEX(Posisi,MATCH(D20,Type,0))} -> Neraca | F20: {=IFERROR(INDEX(SaldoNormal,MATCH(D20,Type,)),"")} -> Kredit | G20: {=IFERROR(INDEX(COA_DEBET,MATCH(B20,KODEAKUN,0)),"")} -> 0 | H20: {=IFERROR(INDEX(COA_KREDIT,MATCH(B20,KODEAKUN,0)),"")} -> 0 | I20: =IF(B20="","",SUMIF(JU_Kodeakun,B20,JU_Debet)) -> 0 | J20: =IF(B20="","",SUMIF(JU_Kodeakun,B20,JU_Kredit)) -> 0 | K20: =IF(F20="Debet",G20+I20-H20-J20,0) -> 0 | L20: =IF(F20="Kredit",H20+J20-G20-I20,0) -> 0 | M20: =IF(E20="Laba Rugi",K20,0) -> 0 | N20: =IF(E20="Laba Rugi",L20,0) -> 0 | O20: =IF(E20="Neraca",K20,0) -> 0 | P20: =IF(E20="Neraca",L20,0) -> 0 | R20: =IF(AND(G25=0,H25=0,I25=0,J25=0,K25=0,L25=0,M25=0,N25=0,O25=0,P25=0),0,1) -> 1
B21: =IF(COA!B18="","",COA!B18) -> 2160 | C21: {=IFERROR(INDEX(Nama_Akun,MATCH(B21,KODEAKUN,0)),"")} -> utang pcp | D21: {=IFERROR(INDEX(Type,MATCH(B21,KODEAKUN,0)),"")} -> utang pcp | E21: {=INDEX(Posisi,MATCH(D21,Type,0))} -> Neraca | F21: {=IFERROR(INDEX(SaldoNormal,MATCH(D21,Type,)),"")} -> Kredit | G21: {=IFERROR(INDEX(COA_DEBET,MATCH(B21,KODEAKUN,0)),"")} -> 0 | H21: {=IFERROR(INDEX(COA_KREDIT,MATCH(B21,KODEAKUN,0)),"")} -> 0 | I21: =IF(B21="","",SUMIF(JU_Kodeakun,B21,JU_Debet)) -> 0 | J21: =IF(B21="","",SUMIF(JU_Kodeakun,B21,JU_Kredit)) -> 0 | K21: =IF(F21="Debet",G21+I21-H21-J21,0) -> 0 | L21: =IF(F21="Kredit",H21+J21-G21-I21,0) -> 0 | M21: =IF(E21="Laba Rugi",K21,0) -> 0 | N21: =IF(E21="Laba Rugi",L21,0) -> 0 | O21: =IF(E21="Neraca",K21,0) -> 0 | P21: =IF(E21="Neraca",L21,0) -> 0 | R21: =IF(AND(G26=0,H26=0,I26=0,J26=0,K26=0,L26=0,M26=0,N26=0,O26=0,P26=0),0,1) -> 0
B22: =IF(COA!B19="","",COA!B19) -> 3100 | C22: {=IFERROR(INDEX(Nama_Akun,MATCH(B22,KODEAKUN,0)),"")} -> Modal | D22: {=IFERROR(INDEX(Type,MATCH(B22,KODEAKUN,0)),"")} -> Modal | E22: {=INDEX(Posisi,MATCH(D22,Type,0))} -> Neraca | F22: {=IFERROR(INDEX(SaldoNormal,MATCH(D22,Type,)),"")} -> Kredit | G22: {=IFERROR(INDEX(COA_DEBET,MATCH(B22,KODEAKUN,0)),"")} -> 0 | H22: {=IFERROR(INDEX(COA_KREDIT,MATCH(B22,KODEAKUN,0)),"")} -> 0 | I22: =IF(B22="","",SUMIF(JU_Kodeakun,B22,JU_Debet)) -> 0 | J22: =IF(B22="","",SUMIF(JU_Kodeakun,B22,JU_Kredit)) -> 0 | K22: =IF(F22="Debet",G22+I22-H22-J22,0) -> 0 | L22: =IF(F22="Kredit",H22+J22-G22-I22,0) -> 0 | M22: =IF(E22="Laba Rugi",K22,0) -> 0 | N22: =IF(E22="Laba Rugi",L22,0) -> 0 | O22: =IF(E22="Neraca",K22,0) -> 0 | P22: =IF(E22="Neraca",L22,0) -> 0 | R22: =IF(AND(G27=0,H27=0,I27=0,J27=0,K27=0,L27=0,M27=0,N27=0,O27=0,P27=0),0,1) -> 1
B23: =IF(COA!B20="","",COA!B20) -> 3110 | C23: {=IFERROR(INDEX(Nama_Akun,MATCH(B23,KODEAKUN,0)),"")} -> Iktisar laba rugi | D23: {=IFERROR(INDEX(Type,MATCH(B23,KODEAKUN,0)),"")} -> Iktisar laba rugi | E23: {=INDEX(Posisi,MATCH(D23,Type,0))} -> Neraca | F23: {=IFERROR(INDEX(SaldoNormal,MATCH(D23,Type,)),"")} -> Kredit | G23: {=IFERROR(INDEX(COA_DEBET,MATCH(B23,KODEAKUN,0)),"")} -> 0 | H23: {=IFERROR(INDEX(COA_KREDIT,MATCH(B23,KODEAKUN,0)),"")} -> 0 | I23: =IF(B23="","",SUMIF(JU_Kodeakun,B23,JU_Debet)) -> 0 | J23: =IF(B23="","",SUMIF(JU_Kodeakun,B23,JU_Kredit)) -> 0 | K23: =IF(F23="Debet",G23+I23-H23-J23,0) -> 0 | L23: =IF(F23="Kredit",H23+J23-G23-I23,0) -> 0 | M23: =IF(E23="Laba Rugi",K23,0) -> 0 | N23: =IF(E23="Laba Rugi",L23,0) -> 0 | O23: =IF(E23="Neraca",K23,0) -> 0 | P23: =IF(E23="Neraca",L23,0) -> 0 | R23: =IF(AND(G28=0,H28=0,I28=0,J28=0,K28=0,L28=0,M28=0,N28=0,O28=0,P28=0),0,1) -> 1
B24: =IF(COA!B21="","",COA!B21) -> 4110 | C24: {=IFERROR(INDEX(Nama_Akun,MATCH(B24,KODEAKUN,0)),"")} -> Pendapatan jasa | D24: {=IFERROR(INDEX(Type,MATCH(B24,KODEAKUN,0)),"")} -> Pendapatan jasa | E24: {=INDEX(Posisi,MATCH(D24,Type,0))} -> Laba Rugi | F24: {=IFERROR(INDEX(SaldoNormal,MATCH(D24,Type,)),"")} -> Kredit | G24: {=IFERROR(INDEX(COA_DEBET,MATCH(B24,KODEAKUN,0)),"")} -> 0 | H24: {=IFERROR(INDEX(COA_KREDIT,MATCH(B24,KODEAKUN,0)),"")} -> 0 | I24: =IF(B24="","",SUMIF(JU_Kodeakun,B24,JU_Debet)) -> 124642329 | J24: =IF(B24="","",SUMIF(JU_Kodeakun,B24,JU_Kredit)) -> 0 | K24: =IF(F24="Debet",G24+I24-H24-J24,0) -> 0 | L24: =IF(F24="Kredit",H24+J24-G24-I24,0) -> -124642329 | M24: =IF(E24="Laba Rugi",K24,0) -> 0 | N24: =IF(E24="Laba Rugi",L24,0) -> -124642329 | O24: =IF(E24="Neraca",K24,0) -> 0 | P24: =IF(E24="Neraca",L24,0) -> 0 | R24: =IF(AND(G29=0,H29=0,I29=0,J29=0,K29=0,L29=0,M29=0,N29=0,O29=0,P29=0),0,1) -> 0
B25: =IF(COA!B22="","",COA!B22) -> 4120 | C25: {=IFERROR(INDEX(Nama_Akun,MATCH(B25,KODEAKUN,0)),"")} -> pendapatan shoepolice | D25: {=IFERROR(INDEX(Type,MATCH(B25,KODEAKUN,0)),"")} -> pendapatan shoepolice | E25: {=INDEX(Posisi,MATCH(D25,Type,0))} -> Laba Rugi | F25: {=IFERROR(INDEX(SaldoNormal,MATCH(D25,Type,)),"")} -> Kredit | G25: {=IFERROR(INDEX(COA_DEBET,MATCH(B25,KODEAKUN,0)),"")} -> 0 | H25: {=IFERROR(INDEX(COA_KREDIT,MATCH(B25,KODEAKUN,0)),"")} -> 0 | I25: =IF(B25="","",SUMIF(JU_Kodeakun,B25,JU_Debet)) -> 2000000 | J25: =IF(B25="","",SUMIF(JU_Kodeakun,B25,JU_Kredit)) -> 0 | K25: =IF(F25="Debet",G25+I25-H25-J25,0) -> 0 | L25: =IF(F25="Kredit",H25+J25-G25-I25,0) -> -2000000 | M25: =IF(E25="Laba Rugi",K25,0) -> 0 | N25: =IF(E25="Laba Rugi",L25,0) -> -2000000 | O25: =IF(E25="Neraca",K25,0) -> 0 | P25: =IF(E25="Neraca",L25,0) -> 0 | R25: =IF(AND(G30=0,H30=0,I30=0,J30=0,K30=0,L30=0,M30=0,N30=0,O30=0,P30=0),0,1) -> 1
B26: =IF(COA!B23="","",COA!B23) -> 4130 | C26: {=IFERROR(INDEX(Nama_Akun,MATCH(B26,KODEAKUN,0)),"")} -> pendapatan affiliate | D26: {=IFERROR(INDEX(Type,MATCH(B26,KODEAKUN,0)),"")} -> pendapatan affiliate | E26: {=INDEX(Posisi,MATCH(D26,Type,0))} -> Laba Rugi | F26: {=IFERROR(INDEX(SaldoNormal,MATCH(D26,Type,)),"")} -> Kredit | G26: {=IFERROR(INDEX(COA_DEBET,MATCH(B26,KODEAKUN,0)),"")} -> 0 | H26: {=IFERROR(INDEX(COA_KREDIT,MATCH(B26,KODEAKUN,0)),"")} -> 0 | I26: =IF(B26="","",SUMIF(JU_Kodeakun,B26,JU_Debet)) -> 0 | J26: =IF(B26="","",SUMIF(JU_Kodeakun,B26,JU_Kredit)) -> 0 | K26: =IF(F26="Debet",G26+I26-H26-J26,0) -> 0 | L26: =IF(F26="Kredit",H26+J26-G26-I26,0) -> 0 | M26: =IF(E26="Laba Rugi",K26,0) -> 0 | N26: =IF(E26="Laba Rugi",L26,0) -> 0 | O26: =IF(E26="Neraca",K26,0) -> 0 | P26: =IF(E26="Neraca",L26,0) -> 0 | R26: =IF(AND(G31=0,H31=0,I31=0,J31=0,K31=0,L31=0,M31=0,N31=0,O31=0,P31=0),0,1) -> 1
B27: =IF(COA!B24="","",COA!B24) -> 4140 | C27: {=IFERROR(INDEX(Nama_Akun,MATCH(B27,KODEAKUN,0)),"")} -> pendapatan jasa eiger | D27: {=IFERROR(INDEX(Type,MATCH(B27,KODEAKUN,0)),"")} -> pendapatan jasa eiger | E27: {=INDEX(Posisi,MATCH(D27,Type,0))} -> Laba Rugi | F27: {=IFERROR(INDEX(SaldoNormal,MATCH(D27,Type,)),"")} -> Kredit | G27: {=IFERROR(INDEX(COA_DEBET,MATCH(B27,KODEAKUN,0)),"")} -> 0 | H27: {=IFERROR(INDEX(COA_KREDIT,MATCH(B27,KODEAKUN,0)),"")} -> 0 | I27: =IF(B27="","",SUMIF(JU_Kodeakun,B27,JU_Debet)) -> 1663000 | J27: =IF(B27="","",SUMIF(JU_Kodeakun,B27,JU_Kredit)) -> 0 | K27: =IF(F27="Debet",G27+I27-H27-J27,0) -> 0 | L27: =IF(F27="Kredit",H27+J27-G27-I27,0) -> -1663000 | M27: =IF(E27="Laba Rugi",K27,0) -> 0 | N27: =IF(E27="Laba Rugi",L27,0) -> -1663000 | O27: =IF(E27="Neraca",K27,0) -> 0 | P27: =IF(E27="Neraca",L27,0) -> 0 | R27: =IF(AND(G32=0,H32=0,I32=0,J32=0,K32=0,L32=0,M32=0,N32=0,O32=0,P32=0),0,1) -> 1
B28: =IF(COA!B25="","",COA!B25) -> 7010 | C28: {=IFERROR(INDEX(Nama_Akun,MATCH(B28,KODEAKUN,0)),"")} -> pendapatan lain-lain | D28: {=IFERROR(INDEX(Type,MATCH(B28,KODEAKUN,0)),"")} -> pendapatan lain-lain | E28: {=INDEX(Posisi,MATCH(D28,Type,0))} -> Laba Rugi | F28: {=IFERROR(INDEX(SaldoNormal,MATCH(D28,Type,)),"")} -> Kredit | G28: {=IFERROR(INDEX(COA_DEBET,MATCH(B28,KODEAKUN,0)),"")} -> 0 | H28: {=IFERROR(INDEX(COA_KREDIT,MATCH(B28,KODEAKUN,0)),"")} -> 0 | I28: =IF(B28="","",SUMIF(JU_Kodeakun,B28,JU_Debet)) -> 349000 | J28: =IF(B28="","",SUMIF(JU_Kodeakun,B28,JU_Kredit)) -> 0 | K28: =IF(F28="Debet",G28+I28-H28-J28,0) -> 0 | L28: =IF(F28="Kredit",H28+J28-G28-I28,0) -> -349000 | M28: =IF(E28="Laba Rugi",K28,0) -> 0 | N28: =IF(E28="Laba Rugi",L28,0) -> -349000 | O28: =IF(E28="Neraca",K28,0) -> 0 | P28: =IF(E28="Neraca",L28,0) -> 0 | R28: =IF(AND(G33=0,H33=0,I33=0,J33=0,K33=0,L33=0,M33=0,N33=0,O33=0,P33=0),0,1) -> 1
B29: =IF(COA!B26="","",COA!B26) -> 4160 | C29: {=IFERROR(INDEX(Nama_Akun,MATCH(B29,KODEAKUN,0)),"")} -> pendapatan ongkir | D29: {=IFERROR(INDEX(Type,MATCH(B29,KODEAKUN,0)),"")} -> pendapatan ongkir | E29: {=INDEX(Posisi,MATCH(D29,Type,0))} -> Laba Rugi | F29: {=IFERROR(INDEX(SaldoNormal,MATCH(D29,Type,)),"")} -> Kredit | G29: {=IFERROR(INDEX(COA_DEBET,MATCH(B29,KODEAKUN,0)),"")} -> 0 | H29: {=IFERROR(INDEX(COA_KREDIT,MATCH(B29,KODEAKUN,0)),"")} -> 0 | I29: =IF(B29="","",SUMIF(JU_Kodeakun,B29,JU_Debet)) -> 0 | J29: =IF(B29="","",SUMIF(JU_Kodeakun,B29,JU_Kredit)) -> 0 | K29: =IF(F29="Debet",G29+I29-H29-J29,0) -> 0 | L29: =IF(F29="Kredit",H29+J29-G29-I29,0) -> 0 | M29: =IF(E29="Laba Rugi",K29,0) -> 0 | N29: =IF(E29="Laba Rugi",L29,0) -> 0 | O29: =IF(E29="Neraca",K29,0) -> 0 | P29: =IF(E29="Neraca",L29,0) -> 0 | R29: =IF(AND(G34=0,H34=0,I34=0,J34=0,K34=0,L34=0,M34=0,N34=0,O34=0,P34=0),0,1) -> 1
B30: =IF(COA!B27="","",COA!B27) -> 4170 | C30: {=IFERROR(INDEX(Nama_Akun,MATCH(B30,KODEAKUN,0)),"")} -> Retur & Refund | D30: {=IFERROR(INDEX(Type,MATCH(B30,KODEAKUN,0)),"")} -> Retur & Refund | E30: {=INDEX(Posisi,MATCH(D30,Type,0))} -> Laba Rugi | F30: {=IFERROR(INDEX(SaldoNormal,MATCH(D30,Type,)),"")} -> Debet | G30: {=IFERROR(INDEX(COA_DEBET,MATCH(B30,KODEAKUN,0)),"")} -> 0 | H30: {=IFERROR(INDEX(COA_KREDIT,MATCH(B30,KODEAKUN,0)),"")} -> 0 | I30: =IF(B30="","",SUMIF(JU_Kodeakun,B30,JU_Debet)) -> 0 | J30: =IF(B30="","",SUMIF(JU_Kodeakun,B30,JU_Kredit)) -> 150000 | K30: =IF(F30="Debet",G30+I30-H30-J30,0) -> -150000 | L30: =IF(F30="Kredit",H30+J30-G30-I30,0) -> 0 | M30: =IF(E30="Laba Rugi",K30,0) -> -150000 | N30: =IF(E30="Laba Rugi",L30,0) -> 0 | O30: =IF(E30="Neraca",K30,0) -> 0 | P30: =IF(E30="Neraca",L30,0) -> 0 | R30: =IF(AND(G35=0,H35=0,I35=0,J35=0,K35=0,L35=0,M35=0,N35=0,O35=0,P35=0),0,1) -> 0
B31: =IF(COA!B28="","",COA!B28) -> 5010 | C31: {=IFERROR(INDEX(Nama_Akun,MATCH(B31,KODEAKUN,0)),"")} -> Hpp sole | D31: {=IFERROR(INDEX(Type,MATCH(B31,KODEAKUN,0)),"")} -> Hpp sole | E31: {=INDEX(Posisi,MATCH(D31,Type,0))} -> Laba Rugi | F31: {=IFERROR(INDEX(SaldoNormal,MATCH(D31,Type,)),"")} -> Debet | G31: {=IFERROR(INDEX(COA_DEBET,MATCH(B31,KODEAKUN,0)),"")} -> 0 | H31: {=IFERROR(INDEX(COA_KREDIT,MATCH(B31,KODEAKUN,0)),"")} -> 0 | I31: =IF(B31="","",SUMIF(JU_Kodeakun,B31,JU_Debet)) -> 0 | J31: =IF(B31="","",SUMIF(JU_Kodeakun,B31,JU_Kredit)) -> 6006717 | K31: =IF(F31="Debet",G31+I31-H31-J31,0) -> -6006717 | L31: =IF(F31="Kredit",H31+J31-G31-I31,0) -> 0 | M31: =IF(E31="Laba Rugi",K31,0) -> -6006717 | N31: =IF(E31="Laba Rugi",L31,0) -> 0 | O31: =IF(E31="Neraca",K31,0) -> 0 | P31: =IF(E31="Neraca",L31,0) -> 0 | R31: =IF(AND(G36=0,H36=0,I36=0,J36=0,K36=0,L36=0,M36=0,N36=0,O36=0,P36=0),0,1) -> 0
... B34: =IF(COA!B31="","",COA!B31) -> 5040 | C34: {=IFERROR(INDEX(Nama_Akun,MATCH(B34,KODEAKUN,0)),"")} -> Hpp Vibram | D34: {=IFERROR(INDEX(Type,MATCH(B34,KODEAKUN,0)),"")} -> Hpp Vibram | E34: {=INDEX(Posisi,MATCH(D34,Type,0))} -> Laba Rugi | F34: {=IFERROR(INDEX(SaldoNormal,MATCH(D34,Type,)),"")} -> Debet | G34: {=IFERROR(INDEX(COA_DEBET,MATCH(B34,KODEAKUN,0)),"")} -> 0 | H34: {=IFERROR(INDEX(COA_KREDIT,MATCH(B34,KODEAKUN,0)),"")} -> 0 | I34: =IF(B34="","",SUMIF(JU_Kodeakun,B34,JU_Debet)) -> 0 | J34: =IF(B34="","",SUMIF(JU_Kodeakun,B34,JU_Kredit)) -> 497000 | K34: =IF(F34="Debet",G34+I34-H34-J34,0) -> -497000 | L34: =IF(F34="Kredit",H34+J34-G34-I34,0) -> 0 | M34: =IF(E34="Laba Rugi",K34,0) -> -497000 | N34: =IF(E34="Laba Rugi",L34,0) -> 0 | O34: =IF(E34="Neraca",K34,0) -> 0 | P34: =IF(E34="Neraca",L34,0) -> 0 | R34: =IF(AND(G39=0,H39=0,I39=0,J39=0,K39=0,L39=0,M39=0,N39=0,O39=0,P39=0),0,1) -> 1
B35: =IF(COA!B32="","",COA!B32) -> 5050 | C35: {=IFERROR(INDEX(Nama_Akun,MATCH(B35,KODEAKUN,0)),"")} -> Hpp repaint | G35: {=IFERROR(INDEX(COA_DEBET,MATCH(B35,KODEAKUN,0)),"")} -> 0 | H35: {=IFERROR(INDEX(COA_KREDIT,MATCH(B35,KODEAKUN,0)),"")} -> 0 | I35: =IF(B35="","",SUMIF(JU_Kodeakun,B35,JU_Debet)) -> 0 | J35: =IF(B35="","",SUMIF(JU_Kodeakun,B35,JU_Kredit)) -> 0 | K35: =IF(F35="Debet",G35+I35-H35-J35,0) -> 0 | L35: =IF(F35="Kredit",H35+J35-G35-I35,0) -> 0 | M35: =IF(E35="Laba Rugi",K35,0) -> 0 | N35: =IF(E35="Laba Rugi",L35,0) -> 0 | O35: =IF(E35="Neraca",K35,0) -> 0 | P35: =IF(E35="Neraca",L35,0) -> 0 | R35: =IF(AND(G40=0,H40=0,I40=0,J40=0,K40=0,L40=0,M40=0,N40=0,O40=0,P40=0),0,1) -> 0
B36: =IF(COA!B33="","",COA!B33) -> 5060 | C36: {=IFERROR(INDEX(Nama_Akun,MATCH(B36,KODEAKUN,0)),"")} -> Hpp general | G36: {=IFERROR(INDEX(COA_DEBET,MATCH(B36,KODEAKUN,0)),"")} -> 0 | H36: {=IFERROR(INDEX(COA_KREDIT,MATCH(B36,KODEAKUN,0)),"")} -> 0 | I36: =IF(B36="","",SUMIF(JU_Kodeakun,B36,JU_Debet)) -> 0 | J36: =IF(B36="","",SUMIF(JU_Kodeakun,B36,JU_Kredit)) -> 0 | K36: =IF(F36="Debet",G36+I36-H36-J36,0) -> 0 | L36: =IF(F36="Kredit",H36+J36-G36-I36,0) -> 0 | M36: =IF(E36="Laba Rugi",K36,0) -> 0 | N36: =IF(E36="Laba Rugi",L36,0) -> 0 | O36: =IF(E36="Neraca",K36,0) -> 0 | P36: =IF(E36="Neraca",L36,0) -> 0 | R36: =IF(AND(G41=0,H41=0,I41=0,J41=0,K41=0,L41=0,M41=0,N41=0,O41=0,P41=0),0,1) -> 0
B37: =IF(COA!B34="","",COA!B34) -> 5070 | C37: {=IFERROR(INDEX(Nama_Akun,MATCH(B37,KODEAKUN,0)),"")} -> Hpp Aksesoris | G37: {=IFERROR(INDEX(COA_DEBET,MATCH(B37,KODEAKUN,0)),"")} -> 0 | H37: {=IFERROR(INDEX(COA_KREDIT,MATCH(B37,KODEAKUN,0)),"")} -> 0 | I37: =IF(B37="","",SUMIF(JU_Kodeakun,B37,JU_Debet)) -> 0 | J37: =IF(B37="","",SUMIF(JU_Kodeakun,B37,JU_Kredit)) -> 50000 | K37: =IF(F37="Debet",G37+I37-H37-J37,0) -> 0 | L37: =IF(F37="Kredit",H37+J37-G37-I37,0) -> 0 | M37: =IF(E37="Laba Rugi",K37,0) -> 0 | N37: =IF(E37="Laba Rugi",L37,0) -> 0 | O37: =IF(E37="Neraca",K37,0) -> 0 | P37: =IF(E37="Neraca",L37,0) -> 0 | R37: =IF(AND(G42=0,H42=0,I42=0,J42=0,K42=0,L42=0,M42=0,N42=0,O42=0,P42=0),0,1) -> 0
B38: =IF(COA!B35="","",COA!B35) -> 5101 | C38: {=IFERROR(INDEX(Nama_Akun,MATCH(B38,KODEAKUN,0)),"")} -> Beban Gaji shoepolice | G38: {=IFERROR(INDEX(COA_DEBET,MATCH(B38,KODEAKUN,0)),"")} -> 0 | H38: {=IFERROR(INDEX(COA_KREDIT,MATCH(B38,KODEAKUN,0)),"")} -> 0 | I38: =IF(B38="","",SUMIF(JU_Kodeakun,B38,JU_Debet)) -> 0 | J38: =IF(B38="","",SUMIF(JU_Kodeakun,B38,JU_Kredit)) -> 0 | K38: =IF(F38="Debet",G38+I38-H38-J38,0) -> 0 | L38: =IF(F38="Kredit",H38+J38-G38-I38,0) -> 0 | M38: =IF(E38="Laba Rugi",K38,0) -> 0 | N38: =IF(E38="Laba Rugi",L38,0) -> 0 | O38: =IF(E38="Neraca",K38,0) -> 0 | P38: =IF(E38="Neraca",L38,0) -> 0 | R38: =IF(AND(G43=0,H43=0,I43=0,J43=0,K43=0,L43=0,M43=0,N43=0,O43=0,P43=0),0,1) -> 0
B39: =IF(COA!B36="","",COA!B36) -> 5102 | C39: {=IFERROR(INDEX(Nama_Akun,MATCH(B39,KODEAKUN,0)),"")} -> Beban Gaji Workshop | G39: {=IFERROR(INDEX(COA_DEBET,MATCH(B39,KODEAKUN,0)),"")} -> 0 | H39: {=IFERROR(INDEX(COA_KREDIT,MATCH(B39,KODEAKUN,0)),"")} -> 0 | I39: =IF(B39="","",SUMIF(JU_Kodeakun,B39,JU_Debet)) -> 0 | J39: =IF(B39="","",SUMIF(JU_Kodeakun,B39,JU_Kredit)) -> 500000 | K39: =IF(F39="Debet",G39+I39-H39-J39,0) -> 0 | L39: =IF(F39="Kredit",H39+J39-G39-I39,0) -> 0 | M39: =IF(E39="Laba Rugi",K39,0) -> 0 | N39: =IF(E39="Laba Rugi",L39,0) -> 0 | O39: =IF(E39="Neraca",K39,0) -> 0 | P39: =IF(E39="Neraca",L39,0) -> 0 | R39: =IF(AND(G44=0,H44=0,I44=0,J44=0,K44=0,L44=0,M44=0,N44=0,O44=0,P44=0),0,1) -> 1
B40: =IF(COA!B37="","",COA!B37) -> 5103 | C40: {=IFERROR(INDEX(Nama_Akun,MATCH(B40,KODEAKUN,0)),"")} -> Beban Gaji CS | G40: {=IFERROR(INDEX(COA_DEBET,MATCH(B40,KODEAKUN,0)),"")} -> 0 | H40: {=IFERROR(INDEX(COA_KREDIT,MATCH(B40,KODEAKUN,0)),"")} -> 0 | I40: =IF(B40="","",SUMIF(JU_Kodeakun,B40,JU_Debet)) -> 0 | J40: =IF(B40="","",SUMIF(JU_Kodeakun,B40,JU_Kredit)) -> 0 | K40: =IF(F40="Debet",G40+I40-H40-J40,0) -> 0 | L40: =IF(F40="Kredit",H40+J40-G40-I40,0) -> 0 | M40: =IF(E40="Laba Rugi",K40,0) -> 0 | N40: =IF(E40="Laba Rugi",L40,0) -> 0 | O40: =IF(E40="Neraca",K40,0) -> 0 | P40: =IF(E40="Neraca",L40,0) -> 0 | R40: =IF(AND(G45=0,H45=0,I45=0,J45=0,K45=0,L45=0,M45=0,N45=0,O45=0,P45=0),0,1) -> 1
B41: =IF(COA!B38="","",COA!B38) -> 5104 | C41: {=IFERROR(INDEX(Nama_Akun,MATCH(B41,KODEAKUN,0)),"")} -> Beban Gaji Finance | G41: {=IFERROR(INDEX(COA_DEBET,MATCH(B41,KODEAKUN,0)),"")} -> 0 | H41: {=IFERROR(INDEX(COA_KREDIT,MATCH(B41,KODEAKUN,0)),"")} -> 0 | I41: =IF(B41="","",SUMIF(JU_Kodeakun,B41,JU_Debet)) -> 0 | J41: =IF(B41="","",SUMIF(JU_Kodeakun,B41,JU_Kredit)) -> 0 | K41: =IF(F41="Debet",G41+I41-H41-J41,0) -> 0 | L41: =IF(F41="Kredit",H41+J41-G41-I41,0) -> 0 | M41: =IF(E41="Laba Rugi",K41,0) -> 0 | N41: =IF(E41="Laba Rugi",L41,0) -> 0 | O41: =IF(E41="Neraca",K41,0) -> 0 | P41: =IF(E41="Neraca",L41,0) -> 0 | R41: =IF(AND(G46=0,H46=0,I46=0,J46=0,K46=0,L46=0,M46=0,N46=0,O46=0,P46=0),0,1) -> 0
B42: =IF(COA!B39="","",COA!B39) -> 5105 | C42: {=IFERROR(INDEX(Nama_Akun,MATCH(B42,KODEAKUN,0)),"")} -> Beban Gaji CC | G42: {=IFERROR(INDEX(COA_DEBET,MATCH(B42,KODEAKUN,0)),"")} -> 0 | H42: {=IFERROR(INDEX(COA_KREDIT,MATCH(B42,KODEAKUN,0)),"")} -> 0 | I42: =IF(B42="","",SUMIF(JU_Kodeakun,B42,JU_Debet)) -> 0 | J42: =IF(B42="","",SUMIF(JU_Kodeakun,B42,JU_Kredit)) -> 0 | K42: =IF(F42="Debet",G42+I42-H42-J42,0) -> 0 | L42: =IF(F42="Kredit",H42+J42-G42-I42,0) -> 0 | M42: =IF(E42="Laba Rugi",K42,0) -> 0 | N42: =IF(E42="Laba Rugi",L42,0) -> 0 | O42: =IF(E42="Neraca",K42,0) -> 0 | P42: =IF(E42="Neraca",L42,0) -> 0 | R42: =IF(AND(G47=0,H47=0,I47=0,J47=0,K47=0,L47=0,M47=0,N47=0,O47=0,P47=0),0,1) -> 0
B43: =IF(COA!B40="","",COA!B40) -> 5106 | C43: {=IFERROR(INDEX(Nama_Akun,MATCH(B43,KODEAKUN,0)),"")} -> Beban Gaji Data analisis | G43: {=IFERROR(INDEX(COA_DEBET,MATCH(B43,KODEAKUN,0)),"")} -> 0 | H43: {=IFERROR(INDEX(COA_KREDIT,MATCH(B43,KODEAKUN,0)),"")} -> 0 | I43: =IF(B43="","",SUMIF(JU_Kodeakun,B43,JU_Debet)) -> 0 | J43: =IF(B43="","",SUMIF(JU_Kodeakun,B43,JU_Kredit)) -> 0 | K43: =IF(F43="Debet",G43+I43-H43-J43,0) -> 0 | L43: =IF(F43="Kredit",H43+J43-G43-I43,0) -> 0 | M43: =IF(E43="Laba Rugi",K43,0) -> 0 | N43: =IF(E43="Laba Rugi",L43,0) -> 0 | O43: =IF(E43="Neraca",K43,0) -> 0 | P43: =IF(E43="Neraca",L43,0) -> 0 | R43: =IF(AND(G48=0,H48=0,I48=0,J48=0,K48=0,L48=0,M48=0,N48=0,O48=0,P48=0),0,1) -> 0
B44: =IF(COA!B41="","",COA!B41) -> 5107 | C44: {=IFERROR(INDEX(Nama_Akun,MATCH(B44,KODEAKUN,0)),"")} -> Beban Gaji Gudang | G44: {=IFERROR(INDEX(COA_DEBET,MATCH(B44,KODEAKUN,0)),"")} -> 0 | H44: {=IFERROR(INDEX(COA_KREDIT,MATCH(B44,KODEAKUN,0)),"")} -> 0 | I44: =IF(B44="","",SUMIF(JU_Kodeakun,B44,JU_Debet)) -> 0 | J44: =IF(B44="","",SUMIF(JU_Kodeakun,B44,JU_Kredit)) -> 583333 | K44: =IF(F44="Debet",G44+I44-H44-J44,0) -> 0 | L44: =IF(F44="Kredit",H44+J44-G44-I44,0) -> 0 | M44: =IF(E44="Laba Rugi",K44,0) -> 0 | N44: =IF(E44="Laba Rugi",L44,0) -> 0 | O44: =IF(E44="Neraca",K44,0) -> 0 | P44: =IF(E44="Neraca",L44,0) -> 0 | R44: =IF(AND(G49=0,H49=0,I49=0,J49=0,K49=0,L49=0,M49=0,N49=0,O49=0,P49=0),0,1) -> 1
...

Sheet LR
B2: =NRL!B2 -> PT. TERANG GARAM SOLUSINDO | O2: PT. TERANG GARAM SOLUSINDO
B3: LABA (RUGI) OFFICE & WS | O3: LABA (RUGI) OFFICE & WS
B4: =NRL!B4 -> PERIODE | O4: PER MEI 2026 (28 april - 27 mei 2026)
O5: 40.00.00.00 | P5: PENDAPATAN
B6: KODE | C6: KETERANGAN | D6: SALDO | G6: KB DEBET | H6: KB KREDIT | I6: SN | L6: KETERANGAN | M6: SALDO | O6: 41.00.00.00 | P6: pendapatan jasa | Q6: 284789665 | R6: 0.9575
J7: PENDAPATAN | K7: =D9 -> -124642329 | O7: 43.00.00.00 | P7: pendapatan ongkir | Q7: 12643912 | R7: 0.0425
